Workbook

Sheet README
A1: ADAM + NetStreamX — Fully Sovereign On-Prem Cost & Revenue Model v1.1
A3: SCENARIO
A4: Full production deployment of the ADAM framework (CORE Engine, 81-Agent Mesh, BOSS Scoring, Flight Recorder, Governance Plane) on a FULLY SOVEREIGN on-premises substrate, hosting the NetStreamX streaming workload at 1,000,000 subscribers and a 100,000-title UHD catalog (average 2-hour H.265/AV1 films).
A6: DEPLOYMENT ARCHITECTURE
A7: Reference: ADAM_Fully_Sovereign_OnPrem_V2.0.drawio. Dual-DC active/active on bare-metal Kubernetes; on-prem LLM (Llama 3 / Mistral) for AI/governance inference; Ceph (object+block) and MinIO WORM for Flight Recorder; Postgres HA, Neo4j/ArangoDB, Weaviate/Milvus, Kafka/Redpanda, NATS, Temporal; Thales/Luna HSM (FIPS L3); HashiCorp Vault; Keycloak/AD; SPIRE/SPIFFE workload identity; Wazuh/ELK SIEM; Falco+Tetragon runtime; Grafana+Loki+Mimir; BGP+EVPN fabric, MACsec+IPsec, sovereign anycast DNS. Air-gapped boundary; zero public egress for governance, evidence, or AI inference.
A9: THE PUBLIC-CLOUD REMNANT
A10: Sovereignty is total for governance/data/AI. Public cloud is retained ONLY for global content distribution and edge protection, where physical optimality requires a planetary footprint: (1) external CDN (Akamai or equivalent), (2) DDoS scrubbing / Magic Transit, (3) IX transit and peering, (4) optional secondary anycast support. No customer PII, no Flight Recorder data, no AI inference, no doctrine state ever leaves on-prem perimeter — only encoded video segments and signed manifests.
A12: WHAT'S IN / WHAT'S OUT
A13: IN: All hardware CapEx (compute, GPU, storage, network, HSM, DC fit-out); on-prem OpEx (power, cooling, space, dark fiber, transit, hardware maintenance, software subscriptions, staff, ADAM overlay). External CDN egress; subscriber growth; content amortization; competitive bench. OUT: Acquisition costs of NetStreamX itself; legacy data-center decommissioning; tax/legal entity setup; M&A; one-off marketing campaigns.
A15: METHODOLOGY
A16: Bottom-up engineering build: (1) workload sized from 1M subs / 100K UHD assets / 8.9 Mbps blended bitrate; (2) hardware sized from ADAM DNA Spec resource profile (3,180 vCPU, 12,720 GB RAM, 42 GPU agents) plus streaming origin/transcode/database tier; (3) unit costs from public list prices net of typical enterprise discount (~20-30% on hardware, Microsoft EA / Red Hat ELA on software). CDN priced at 10PB+/month committed-use rate ($0.0085–$0.012/GB), NOT list. Power at €0.12/kWh European average, PUE 1.5. Staff at Western European fully-loaded rates (~$180-220K).
A18: CAPEX vs OPEX
... A28: ADAM Book (Parts IV, VI, IX, XI); ADAM DNA Deployment Specification §8.5 (cost framework); ADAM Governance Charter (5-Director model); ADAM BOSS Score Formulas (exception economy); ADAM Industry-Specific Services Part II (Media); ADAM_Fully_Sovereign_OnPrem_V2.0 architecture diagram.

Sheet Assumptions
A1: Assumptions — All Inputs (BLUE = editable, YELLOW = high-leverage)
A2: Parameter | B2: Value | C2: Unit | D2: Source / Note
A3: ─── Subscriber & Workload ───────────────────────────────
A4: Subscribers (Year 1) | B4: 1000000 | C4: subs | D4: User-specified scale
A5: Daily Active Users (DAU) ratio | B5: 0.35 | C5: ratio | D5: Industry: Netflix ~0.45, niche ~0.25
A6: Average viewing hours / DAU / day | B6: 2 | C6: hours | D6: User-specified
A7: Blended bitrate (40% UHD + 40% HD + 20% SD) | B7: 8.9 | C7: Mbps | D7: 0.4×15 + 0.4×6 + 0.2×2.5
A8: Monthly subscriber egress (PB) | B8: =(B5*B4*B6*30*3600*B7)/8/1024/1024/1024 -> 78.328885 | C8: PB/mo | D8: DAU × hrs × 30 × 3600s × Mbps / 8 / 1024^3
A9: Annual content catalog growth | B9: 0.2 | C9: ratio | D9: 20% new titles per year
A10: Subscriber growth rate (Y2-Y5) | B10: 0.12 | C10: ratio | D10: Mature streaming player growth
A11: ─── Content Library ─────────────────────────────────────
A12: Total titles | B12: 100000 | C12: titles | D12: User-specified
A13: Average title duration | B13: 2 | C13: hours | D13: User-specified
A14: Mezzanine size per UHD title (4K HEVC + Dolby Vision) | B14: 22 | C14: GB | D14: Industry: ~11 GB/hr UHD HEVC
A15: ABR ladder size multiplier (mezzanine + 8 renditions) | B15: 2.5 | C15: x | D15: Renditions ~1.5x mezzanine
A16: Replication factor (Ceph 3x + MinIO erasure 1.5x avg) | B16: 2.5 | C16: x | D16: Per-DC replication overhead
A17: Storage tiering — hot share (NVMe) | B17: 0.1 | C17: ratio | D17: 10% of catalog drives 90% of plays
A18: Total content storage required (raw) | B18: =B12*B14*B15*B16/1048576 -> 13.113022 | C18: PB | D18: titles × GB × ladder × repl / 1024^2
A19: ─── Datacenter Footprint ────────────────────────────────
A20: Datacenter sites (active/active) | B20: 2 | C20: DC | D20: Per ADAM Sovereign architecture
A21: PUE (industry tier-3 colo target) | B21: 1.5 | C21: ratio | D21: European tier-3 colo average
A22: Electricity blended rate (EU) | B22: 0.12 | C22: $/kWh | D22: EU industrial: €0.10-0.14, blended
A23: Rack lease (per rack per month, full power) | B23: 1500 | C23: $/mo | D23: Equinix/Digital Realty EU tier-3
A24: Dark fiber metro DR pair (per month) | B24: 50000 | C24: $/mo | D24: 100G+ redundant dual-metro
A25: Hardware support (% of IT CapEx, blended Y1-Y5) | B25: 0.07 | C25: ratio | D25: Years 1-3 warranty, Y4-5 ramp
A26: CapEx amortization period | B26: 5 | C26: years | D26: Standard data-center 5-year refresh cycle
A27: Sustaining CapEx (Y4-Y5, % original IT CapEx) | B27: 0.15 | C27: ratio | D27: Refresh + capacity grow
A28: ─── Hardware Unit Costs (post-discount) ────────────────
A29: Compute server (2U, dual EPYC Genoa, 1.5TB DDR5) | B29: 48000 | C29: $/server | D29: Dell R760 / HPE DL385 enterprise
A30: GPU server (HGX H100, 8x H100 80GB) | B30: 280000 | C30: $/server | D30: NVIDIA HGX reference, channel pricing
A31: Storage node (24x 22TB HDD, ~528 TB raw) | B31: 32000 | C31: $/node | D31: Dell PowerEdge / Supermicro
A32: NVMe storage node (24x 30TB NVMe, ~720 TB) | B32: 65000 | C32: $/node | D32: All-flash hot tier
A33: Spine switch (400G fabric, 32-port) | B33: 180000 | C33: $/sw | D33: Arista 7800 or Juniper QFX10000
A34: Leaf switch (100G, 48-port) | B34: 35000 | C34: $/sw | D34: Arista 7050X3 or Juniper QFX5120
A35: Border / edge router (BGP, multi-homed) | B35: 120000 | C35: $/sw | D35: Juniper MX240/MX480 or Cisco ASR
A36: DDoS appliance (on-prem) | B36: 80000 | C36: $/unit | D36: Arbor / Radware
A37: Thales Luna HSM (FIPS 140-2 L3) | B37: 80000 | C37: $/unit | D37: PCIe / network HSM
A38: Rack + PDU + cabling (per rack, fully fitted) | B38: 4000 | C38: $/rack | D38: Includes APC/Eaton + structured cabling
A39: Hardware enterprise discount (channel) | B39: 0.2 | C39: ratio | D39: 20-30% off list at this scale
A40: ─── ADAM Workload (from DNA Deployment Spec) ───────────
...

Sheet Workload Sizing
A1: Workload Sizing — Subscriber, Content, and Storage Demand
A2: Metric | B2: Value | C2: Unit | D2: Derivation
A3: Subscribers (Year 1) | B3: =Assumptions!$B$4 -> 1000000 | C3: subs | D3: From Assumptions
A4: DAU (subscribers × ratio) | B4: =Assumptions!$B$4*Assumptions!$B$5 -> 350000 | C4: users | D4: Daily active users
A5: Peak concurrent streams (DAU × 0.10 prime-time ratio) | B5: =Assumptions!$B$4*Assumptions!$B$5*0.1 -> 35000 | C5: streams | D5: Industry prime-time concentration
A6: Peak egress bandwidth (concurrent × bitrate) | B6: =Assumptions!$B$4*Assumptions!$B$5*0.1*Assumptions!$B$7/1000 -> 311.5 | C6: Gbps | D6: Concurrent × Mbps / 1000
A7: Daily egress (DAU × hrs × seconds × Mbps / 8 / 1024^3) | B7: =(Assumptions!$B$4*Assumptions!$B$5*Assumptions!$B$6*3600*Assumptions!$B$7)/8/1024/1024/1024 -> 2.6109628 | C7: PB/day | D7: Formula: see derivation
A8: Monthly egress | B8: =B7*30 -> 78.328885 | C8: PB/mo | D8: Daily × 30
A9: Annual egress | B9: =B7*365 -> 953.00144 | C9: PB/yr | D9: Daily × 365
A10: Content library raw size (UHD + ladder + replication) | B10: =Assumptions!$B$18 -> 13.113022 | C10: PB | D10: From Assumptions
A11: Hot tier (NVMe) — 10% of catalog | B11: =B10*Assumptions!$B$17 -> 1.3113022 | C11: PB | D11: 10% drives 90% of plays
A12: Cold tier (HDD) | B12: =B10-B11 -> 11.80172 | C12: PB | D12: Library minus hot
A13: Flight Recorder cumulative (7 years) | B13: =Assumptions!$B$47*Assumptions!$B$46 -> 84 | C13: PB | D13: WORM, hash-chained, 7y minimum
A14: Total storage required (content + FR) | B14: =B10+B13 -> 97.113022 | C14: PB | D14: Sum of all storage

Sheet Hardware CapEx
A1: Hardware CapEx — Year 0 Build (Dual-DC Active/Active)
A2: Component | B2: Per DC | C2: Total | D2: Unit Cost | E2: Extended | F2: Notes
A3: ─ Compute Servers ─
A4: Streaming origin / edge cache | B4: 30 | C4: =B4*2 -> 60 | D4: =Assumptions!$B$29 -> 48000 | E4: =C4*D4*(1-Assumptions!$B$39) -> 2304000 | F4: 60 servers, content-near origin
A5: Application / microservices (NetStreamX) | B5: 50 | C5: =B5*2 -> 100 | D5: =Assumptions!$B$29 -> 48000 | E5: =C5*D5*(1-Assumptions!$B$39) -> 3840000 | F5: 100 servers, stateless services
A6: Kubernetes control plane + ADAM governance | B6: 20 | C6: =B6*2 -> 40 | D6: =Assumptions!$B$29 -> 48000 | E6: =C6*D6*(1-Assumptions!$B$39) -> 1536000 | F6: Bare-metal k8s + governor agents
A7: Database tier (Postgres, Neo4j, Weaviate) | B7: 12 | C7: =B7*2 -> 24 | D7: =Assumptions!$B$29 -> 48000 | E7: =C7*D7*(1-Assumptions!$B$39) -> 921600 | F7: DNA graph + transactional + vector
A8: Streaming bus (Kafka/Redpanda + NATS) | B8: 8 | C8: =B8*2 -> 16 | D8: =Assumptions!$B$29 -> 48000 | E8: =C8*D8*(1-Assumptions!$B$39) -> 614400 | F8: Intent + saga messaging
A9: ─ GPU Servers ─
A10: On-prem LLM inference (Llama 3 70B / Mistral) | B10: 4 | C10: =B10*2 -> 8 | D10: =Assumptions!$B$30 -> 280000 | E10: =C10*D10*(1-Assumptions!$B$39) -> 1792000 | F10: Replaces Azure OpenAI / Bedrock
A11: Transcoding acceleration (NVENC + AV1) | B11: 2 | C11: =B11*2 -> 4 | D11: =Assumptions!$B$30 -> 280000 | E11: =C11*D11*(1-Assumptions!$B$39) -> 896000 | F11: Live ladder + new asset encode
A12: ML/Twin compute (Digital Twins, Anomaly Detect) | B12: 2 | C12: =B12*2 -> 4 | D12: =Assumptions!$B$30 -> 280000 | E12: =C12*D12*(1-Assumptions!$B$39) -> 896000 | F12: 4 Digital Twins per ADAM Spec
A13: ─ Storage ─
A14: Bulk content storage (Ceph HDD) | B14: =ROUNDUP(('Workload Sizing'!$B$12*1024)/((24*22*0.9)),0) -> 26 | C14: =B14*2 -> 52 | D14: =Assumptions!$B$31 -> 32000 | E14: =C14*D14*(1-Assumptions!$B$39) -> 1331200 | F14: 22TB drives, 24/node, ~85% usable, mirrored across DCs
A15: Hot tier (Ceph NVMe all-flash) | B15: =ROUNDUP(('Workload Sizing'!$B$11*1024)/((24*30*0.9)),0) -> 3 | C15: =B15*2 -> 6 | D15: =Assumptions!$B$32 -> 65000 | E15: =C15*D15*(1-Assumptions!$B$39) -> 312000 | F15: 30TB NVMe, 24/node — drives playback latency
A16: MinIO WORM (Flight Recorder) | B16: =ROUNDUP(('Workload Sizing'!$B$13*1024)/((24*22*0.9)),0) -> 182 | C16: =B16*2 -> 364 | D16: =Assumptions!$B$31 -> 32000 | E16: =C16*D16*(1-Assumptions!$B$39) -> 9318400 | F16: WORM erasure-coded, hash-chained, 7-year
A17: ─ Network ─
A18: Spine switches (400G fabric) | B18: 2 | C18: =B18*2 -> 4 | D18: =Assumptions!$B$33 -> 180000 | E18: =C18*D18*(1-Assumptions!$B$39) -> 576000 | F18: 400G EVPN spine
A19: Leaf switches (100G ToR) | B19: 12 | C19: =B19*2 -> 24 | D19: =Assumptions!$B$34 -> 35000 | E19: =C19*D19*(1-Assumptions!$B$39) -> 672000 | F19: 100G ToR per row
A20: Border / edge routers (BGP multi-homed) | B20: 2 | C20: =B20*2 -> 4 | D20: =Assumptions!$B$35 -> 120000 | E20: =C20*D20*(1-Assumptions!$B$39) -> 384000 | F20: Internet-facing BGP
A21: DDoS appliances (on-prem first line) | B21: 2 | C21: =B21*2 -> 4 | D21: =Assumptions!$B$36 -> 80000 | E21: =C21*D21*(1-Assumptions!$B$39) -> 256000 | F21: Volumetric defense
A22: ─ Security / Crypto ─
A23: Thales Luna HSM (FIPS 140-2 L3) | B23: 2 | C23: =B23*2 -> 4 | D23: =Assumptions!$B$37 -> 80000 | E23: =C23*D23*(1-Assumptions!$B$39) -> 256000 | F23: Per ADAM Spec §6.5
A24: ─ DC Fit-out ─
A25: Racks + PDU + structured cabling | B25: 30 | C25: =B25*2 -> 60 | D25: =Assumptions!$B$38 -> 4000 | E25: =C25*D25*(1-Assumptions!$B$39) -> 192000 | F25: 30 racks/DC, fully fitted
A26: UPS / supplemental cooling / DCIM | B26: 1 | C26: =B26*2 -> 2 | D26: 800000 | E26: =C26*D26 -> 1600000 | F26: DC build-out
A27: Optics, cabling, rack-level kit | B27: 1 | C27: =B27*2 -> 2 | D27: 400000 | E27: =C27*D27 -> 800000 | F27: Bulk cabling and TX
A28: Physical security upgrades (sovereign reqs) | B28: 1 | C28: =B28*2 -> 2 | D28: 300000 | E28: =C28*D28 -> 600000 | F28: Mantraps, biometrics, SIEM cams
A30: HARDWARE SUBTOTAL | E30: =SUM(E3:E28) -> 29097600
A32: ─ Software CapEx (perpetual portion) ─
A33: VMware/Tanzu perpetual (legacy bridge) | E33: 500000 | F33: Optional bridge license
A34: F5 BIG-IP perpetual (chassis) | E34: 400000 | F34: Hardware-bound license
A35: Splunk perpetual cores (legacy) | E35: 300000 | F35: Where retained
A36: DRM client SDKs + studio integrations | E36: 1000000 | F36: Widevine/PlayReady/FairPlay one-off
A38: SOFTWARE CAPEX SUBTOTAL | E38: =SUM(E33:E36) -> 2200000
A40: ─ Professional Services & Build ─
A41: DC commissioning & network buildout | E41: 1500000
A42: ADAM platform integration & customization | E42: 2000000
A43: Migration services (apps, data, identity) | E43: 1000000
A44: Training (initial cohort, certifications) | E44: 400000
...

Sheet On-Prem OpEx
A1: On-Prem OpEx — Annual Run Costs (Power, Space, Maintenance, Software, Staff)
A2: Item | B2: Annual $ | C2: Unit | D2: Driver | E2: Notes
A3: ─ Power & Cooling ─
A4: Electricity (IT × PUE × 8760h × $/kWh) | B4: ='Hardware CapEx'!$B$60*Assumptions!$B$21*8760*Assumptions!$B$22 -> 697260.96 | C4: $/yr | D4: Total IT load × PUE × hours × rate | E4: Two DCs combined
A5: ─ Datacenter Space ─
A6: Rack lease (60 racks × $/rack/mo × 12) | B6: =60*Assumptions!$B$23*12 -> 1080000 | C6: $/yr | D6: Equinix/Digital Realty | E6: 30 racks × 2 DCs
A7: Dark fiber metro DR (annualized) | B7: =Assumptions!$B$24*12 -> 600000 | C7: $/yr | D7: Dual-pair 100G+ | E7: Active/active replication path
A8: ─ Network Connectivity (sovereign external) ─
A9: Internet transit (200 Gbps × $/Mbps × 12) | B9: =Assumptions!$B$51*Assumptions!$B$50*12 -> 960000 | C9: $/yr | D9: 95th percentile commit | E9: EU carrier-grade transit pool
A10: IX peering fees (AMS-IX/DE-CIX/LINX) | B10: 60000 | C10: $/yr | D10: Combined | E10: Connection ports + member fees
A11: BGP / routing services | B11: 24000 | C11: $/yr | D11: Looking-glass + RPKI
A12: ─ Hardware Maintenance & Refresh ─
A13: Hardware support (% of IT CapEx, blended Y1-Y5) | B13: ='Hardware CapEx'!$E$30*Assumptions!$B$25 -> 2036832 | C13: $/yr | D13: Blended after-warranty | E13: Y1-3 mostly under warranty; Y4-5 ramps to 10%
A14: ─ Software Subscriptions (annual) ─
A15: Container platform (Rancher Prime / OpenShift) | B15: =Assumptions!$B$61 -> 300000 | C15: $/yr | D15: Per-server | E15: 240+ servers, multi-cluster
A16: HashiCorp Vault Enterprise | B16: =Assumptions!$B$62 -> 250000 | C16: $/yr | D16: Multi-DC | E16: Per ADAM Spec §6.5
A17: Thales/Luna HSM support | B17: =Assumptions!$B$63 -> 80000 | C17: $/yr | D17: Per appliance | E17: FIPS L3 maintenance
A18: Elastic Enterprise (SIEM) | B18: =Assumptions!$B$64 -> 200000 | C18: $/yr | D18: Per ingest | E18: Wazuh / ELK SIEM stack
A19: Grafana / Loki / Mimir Enterprise | B19: =Assumptions!$B$65 -> 120000 | C19: $/yr | D19: Per metric | E19: Observability platform
A20: F5 BIG-IP support | B20: =Assumptions!$B$66 -> 150000 | C20: $/yr | D20: Per chassis | E20: WAF + global LB
A21: Sysdig (Falco/Tetragon enterprise) | B21: =Assumptions!$B$67 -> 150000 | C21: $/yr | D21: Per cluster | E21: Runtime security
A22: Wazuh enterprise support | B22: =Assumptions!$B$68 -> 80000 | C22: $/yr | D22: Per agent | E22: SIEM/SOAR
A23: Temporal enterprise | B23: =Assumptions!$B$69 -> 100000 | C23: $/yr | D23: Per workflow | E23: Saga orchestration
A24: Anyscale / Ray (LLM inference platform) | B24: =Assumptions!$B$70 -> 250000 | C24: $/yr | D24: Per cluster | E24: On-prem LLM serving
A25: AV1/HEVC codec licensing pool | B25: =Assumptions!$B$71 -> 150000 | C25: $/yr | D25: MPEG LA | E25: Studio compliance
A26: Misc (Postgres, Neo4j, Weaviate enterprise) | B26: =Assumptions!$B$72 -> 220000 | C26: $/yr | D26: Mixed | E26: DBA tooling, monitoring
A27: ─ Staff (in-house, sovereign mode) ─
A28: Engineering staff (platform, SRE, DBA, ML, NetSec, DC, media) | B28: =Assumptions!$B$56*Assumptions!$B$55 -> 7920000 | C28: $/yr | D28: =Assumptions!$B$56&" FTE" -> 33 FTE | E28: On-prem requires ~16 more in-house staff vs cloud-native
A29: Engineering management | B29: =Assumptions!$B$57*Assumptions!$B$55*1.15 -> 1104000 | C29: $/yr | D29: =Assumptions!$B$57&" FTE" -> 4 FTE | E29: Director + EMs, +15% comp loading
A30: Compliance & audit (in-house) | B30: =Assumptions!$B$58*Assumptions!$B$55 -> 480000 | C30: $/yr | D30: =Assumptions!$B$58&" FTE" -> 2 FTE | E30: EU AI Act, DORA, NIS2 in-house counsel
A32: TOTAL ON-PREM OPEX (annual) | B32: =SUM(B3:B30) -> 17012093

Sheet CDN & Net Services
A1: CDN & Network Services — The Sovereign-Permitted Public Cloud Remnant
A2: Item | B2: Annual $ | C2: Unit | D2: Notes
A3: ─ Content Delivery Network ─
A4: Subscriber egress via external CDN (multi-CDN commit) | B4: ='Workload Sizing'!$B$9*1024*1024*Assumptions!$B$49 -> 8494002.7 | C4: $/yr | D4: PB/yr × 1024^2 GB × $/GB at 10PB+ commit. Akamai primary, Cloudflare secondary
A5: Multi-CDN orchestration overhead | B5: =B4*0.05 -> 424700.13 | C5: $/yr | D5: 5% premium for failover routing, mid-tier shielding
A6: Origin shield (CloudFront/Akamai mid-tier) | B6: 240000 | C6: $/yr | D6: Reduces fetch from on-prem origin
A7: DRM transactions (license server bursts) | B7: 180000 | C7: $/yr | D7: Where studio rules prohibit on-prem DRM
A8: ─ Network Edge Services ─
A9: DDoS scrubbing service (Cloudflare Magic / Akamai Prolexic) | B9: =Assumptions!$B$52 -> 360000 | C9: $/yr | D9: Layer 3-7 always-on, sovereign-routed
A10: DRM Service (Widevine / PlayReady / FairPlay) | B10: =Assumptions!$B$53 -> 200000 | C10: $/yr | D10: Studio compliance — license server costs
A11: Anycast DNS overflow / global resolver | B11: 84000 | C11: $/yr | D11: PowerDNS sovereign + Route53/NS1 for global recursive
A12: Threat intel feeds (commercial) | B12: 240000 | C12: $/yr | D12: Recorded Future, Mandiant, Flashpoint
A14: TOTAL CDN + NETWORK SERVICES | B14: =SUM(B3:B12) -> 10222703

Sheet ADAM Governance OpEx
A1: ADAM Governance Overlay — Annual Cost (On-Prem Mode)
A2: Item | B2: Annual $ | C2: Unit | D2: Notes
A3: ─ Human Directorship (allocated portion) ─
A4: Mandatory directors (5) — allocated comp | B4: =Assumptions!$B$75*Assumptions!$B$74 -> 1500000 | C4: $/yr | D4: Per Governance Charter §A.4 — 5-Director Constitution
A5: ─ Compliance & Attestation ─
A6: External annual ADAM compliance audit | B6: =Assumptions!$B$76 -> 400000 | C6: $/yr | D6: Big 4 attestation per book Part XIII
A7: EU AI Act conformity assessment (notified body) | B7: =Assumptions!$B$77 -> 200000 | C7: $/yr | D7: High-risk AI conformity per book §IX.2
A8: DORA registry + NIS2 attestation | B8: =Assumptions!$B$78 -> 120000 | C8: $/yr | D8: Registry maintenance + ICT incident reporting
A9: Doctrine evolution + model governance (legal) | B9: =Assumptions!$B$80 -> 250000 | C9: $/yr | D9: Per Legal & Arbitration §3 doctrine conflict process
A10: Continuous training & certifications | B10: =Assumptions!$B$81 -> 150000 | C10: $/yr | D10: Director + governance staff
A11: ─ Risk Transfer ─
A12: Cyber + D&O insurance (ADAM-amplified premium) | B12: =Assumptions!$B$79 -> 400000 | C12: $/yr | D12: Premium reflects autonomous-system D&O exposure
A13: ─ Operational Overhead (note: AI inference is on-prem) ─
A14: AI inference (replaced by on-prem LLM hardware/power) | B14: 0 | C14: $/yr | D14: Azure OpenAI ~$2-3M/yr SAVED — moved to GPU CapEx + power above
A15: Flight Recorder evidence ingest (storage handled on-prem) | B15: 0 | C15: $/yr | D15: MinIO WORM hardware accounted in CapEx; no cloud cost
A16: Exception Economy operations (BOSS scoring, escalation) | B16: 600000 | C16: $/yr | D16: SOAP→OHSHAT runtime costs above baseline staffing
A18: TOTAL ADAM GOVERNANCE OVERLAY | B18: =SUM(B3:B16) -> 3620000

Sheet Consolidated TCO
A1: Consolidated TCO — Cash View vs. Run-Rate (Amortized) View
A2: Cost Bucket | B2: Annual $ | C2: % of Run-Rate | D2: Per-Sub /mo | E2: Notes
A3: ─ CASH VIEW (Year 1 = build year) ─
A4: Year 0/1 CapEx (full build, paid upfront) | B4: ='Hardware CapEx'!$E$50 -> 40541312 | E4: Hardware + software perpetual + PS + contingency
A5: Year 1 OpEx (full year, on-prem run costs) | B5: ='On-Prem OpEx'!$B$32 -> 17012093 | E5: Power, space, maintenance, software, staff
A6: Year 1 CDN + Network Services | B6: ='CDN & Net Services'!$B$14 -> 10222703
A7: Year 1 ADAM Governance Overlay | B7: ='ADAM Governance OpEx'!$B$18 -> 3620000
A8: TOTAL Year 1 CASH OUTLAY | B8: =SUM(B4:B7) -> 71396108 | D8: =B8/Assumptions!$B$4/12 -> 5.9496756
A10: ─ RUN-RATE VIEW (P&L, CapEx amortized 5y) ─
A11: CapEx amortization (Y1-Y5 each) | B11: ='Hardware CapEx'!$E$51 -> 8108262.4 | C11: =B11/B15 -> 0.20810128 | D11: =B11/Assumptions!$B$4/12 -> 0.67568853 | E11: Total CapEx ÷ 5y
A12: On-Prem OpEx (annual) | B12: ='On-Prem OpEx'!$B$32 -> 17012093 | C12: =B12/B15 -> 0.43662109 | D12: =B12/Assumptions!$B$4/12 -> 1.4176744
A13: CDN + Network Services (annual) | B13: ='CDN & Net Services'!$B$14 -> 10222703 | C13: =B13/B15 -> 0.26236911 | D13: =B13/Assumptions!$B$4/12 -> 0.8518919
A14: ADAM Governance Overlay (annual) | B14: ='ADAM Governance OpEx'!$B$18 -> 3620000 | C14: =B14/B15 -> 0.092908518 | D14: =B14/Assumptions!$B$4/12 -> 0.30166667
A15: TOTAL ANNUAL RUN-RATE | B15: =SUM(B11:B14) -> 38963058 | C15: =1 -> 1 | D15: =B15/Assumptions!$B$4/12 -> 3.2469215

Sheet Revenue Model
A1: Revenue Model — Tier Mix × ARPU × Subscribers
A2: Tier | B2: Mix % | C2: Monthly $ | D2: Subs | E2: Annual $ | F2: Notes
A3: Ad-supported | B3: =Assumptions!$B$83 -> 0.2 | C3: 5.99 | D3: =Assumptions!$B$4*Assumptions!$B$83 -> 200000 | E3: =C3*D3*12 -> 14376000 | G3: Ad-supported entry — pricing-driven growth
A4: Basic SD | B4: =Assumptions!$B$84 -> 0.1 | C4: 9.99 | D4: =Assumptions!$B$4*Assumptions!$B$84 -> 100000 | E4: =C4*D4*12 -> 11988000 | G4: Slim entry, single-stream SD
A5: Standard HD | B5: =Assumptions!$B$85 -> 0.4 | C5: 14.99 | D5: =Assumptions!$B$4*Assumptions!$B$85 -> 400000 | E5: =C5*D5*12 -> 71952000 | G5: Anchor tier — 2 streams, HD
A6: Premium UHD | B6: =Assumptions!$B$86 -> 0.25 | C6: 19.99 | D6: =Assumptions!$B$4*Assumptions!$B$86 -> 250000 | E6: =C6*D6*12 -> 59970000 | G6: 4 streams, UHD, Dolby Vision
A7: Premium Plus (sovereignty bundle) | B7: =Assumptions!$B$87 -> 0.05 | C7: 27.99 | D7: =Assumptions!$B$4*Assumptions!$B$87 -> 50000 | E7: =C7*D7*12 -> 16794000 | G7: NEW: UHD + downloads + sovereign premium + extended catalog
A9: Total subscriber revenue (recommended pricing) | E9: =SUM(E3:E7) -> 175080000
A10: Blended ARPU (per sub per month) | C10: =E9/Assumptions!$B$4/12 -> 14.59
A12: ─ Ad revenue (ad-tier impressions, ARPU uplift) ─
A13: Ad ARPU per ad-tier sub /month (impressions × CPM) | C13: 8.5 | D13: =Assumptions!$B$4*Assumptions!$B$83 -> 200000 | E13: =C13*D13*12 -> 20400000 | G13: Industry: $7-$10 per sub/mo from ads at ~30 mins/day exposure
A15: TOTAL ANNUAL REVENUE (Year 1) | E15: =E9+E13 -> 195480000

Sheet 5-Year P&L
A1: 5-Year P&L — Sovereign On-Prem ADAM + NetStreamX
A2: Line | B2: Year 1 | C2: Year 2 | D2: Year 3 | E2: Year 4 | F2: Year 5 | G2: Notes
A3: Subscribers (year-end) | B3: =Assumptions!$B$4 -> 1000000 | C3: =B3*(1+Assumptions!$B$10) -> 1120000 | D3: =C3*(1+Assumptions!$B$10) -> 1254400 | E3: =D3*(1+Assumptions!$B$10) -> 1404928 | F3: =E3*(1+Assumptions!$B$10) -> 1573519.4 | G3: 12% annual growth Y2-Y5 baseline
A4: Blended subscription ARPU /mo | B4: ='Revenue Model'!$C$10 -> 14.59 | C4: ='Revenue Model'!$C$10 -> 14.59 | D4: ='Revenue Model'!$C$10 -> 14.59 | E4: ='Revenue Model'!$C$10 -> 14.59 | F4: ='Revenue Model'!$C$10 -> 14.59 | G4: Held flat in scenario; pricing changes flex this
A5: Subscription revenue | B5: =B3*B4*12 -> 1.7508e+08 | C5: =C3*C4*12 -> 1.960896e+08 | D5: =D3*D4*12 -> 2.1962035e+08 | E5: =E3*E4*12 -> 2.4597479e+08 | F5: =F3*F4*12 -> 2.7549177e+08
A6: Ad revenue (ad-tier × $8.50/mo × 12) | B6: =B3*Assumptions!$B$83*8.5*12 -> 20400000 | C6: =C3*Assumptions!$B$83*8.5*12 -> 22848000 | D6: =D3*Assumptions!$B$83*8.5*12 -> 25589760 | E6: =E3*Assumptions!$B$83*8.5*12 -> 28660531 | F6: =F3*Assumptions!$B$83*8.5*12 -> 32099795
A7: TOTAL REVENUE | B7: =B5+B6 -> 1.9548e+08 | C7: =C5+C6 -> 2.189376e+08 | D7: =D5+D6 -> 2.4521011e+08 | E7: =E5+E6 -> 2.7463533e+08 | F7: =F5+F6 -> 3.0759156e+08
A9: OPERATING COSTS
A10: Content investment (% of revenue) | B10: =B7*Assumptions!$B$91 -> 82101600 | C10: =C7*Assumptions!$B$91 -> 91953792 | D10: =D7*Assumptions!$B$91 -> 1.0298825e+08 | E10: =E7*Assumptions!$B$91 -> 1.1534684e+08 | F10: =F7*Assumptions!$B$91 -> 1.2918846e+08
A11: Content amortization (P&L impact) | B11: =B10/Assumptions!$B$90 -> 20525400 | C11: =(SUM(B10:C10))/Assumptions!$B$90 -> 43513848 | D11: =(SUM(B10:D10))/Assumptions!$B$90 -> 69260910 | E11: =(SUM(B10:E10))/Assumptions!$B$90 -> 98097619 | F11: =(SUM(C10:F10))/Assumptions!$B$90 -> 1.0986933e+08 | G11: Straight-line over content amortization period
A12: ADAM/IT — CapEx amortization | B12: ='Hardware CapEx'!$E$51 -> 8108262.4 | C12: ='Hardware CapEx'!$E$51 -> 8108262.4 | D12: ='Hardware CapEx'!$E$51 -> 8108262.4 | E12: ='Hardware CapEx'!$E$51 -> 8108262.4 | F12: ='Hardware CapEx'!$E$51 -> 8108262.4 | G12: Straight-line 5-year. Y4-Y5 also gets sustaining CapEx (below).
A13: ADAM/IT — Sustaining CapEx amortization | B13: 0 | C13: 0 | D13: 0 | E13: ='Hardware CapEx'!$E$52 -> 4364640 | F13: =E13+'Hardware CapEx'!$E$52 -> 8729280
A14: On-Prem OpEx | B14: ='On-Prem OpEx'!$B$32 -> 17012093 | C14: ='On-Prem OpEx'!$B$32 -> 17012093 | D14: ='On-Prem OpEx'!$B$32 -> 17012093 | E14: ='On-Prem OpEx'!$B$32 -> 17012093 | F14: ='On-Prem OpEx'!$B$32 -> 17012093
A15: CDN & Network Services (scales with subs) | B15: ='CDN & Net Services'!$B$14 -> 10222703 | C15: =B15*(C3/B3) -> 11449427 | D15: =B15*(D3/B3) -> 12823358 | E15: =B15*(E3/B3) -> 14362161 | F15: =B15*(F3/B3) -> 16085621 | G15: CDN scales linearly with subscriber base
A16: ADAM Governance Overlay | B16: ='ADAM Governance OpEx'!$B$18 -> 3620000 | C16: ='ADAM Governance OpEx'!$B$18 -> 3620000 | D16: ='ADAM Governance OpEx'!$B$18 -> 3620000 | E16: ='ADAM Governance OpEx'!$B$18 -> 3620000 | F16: ='ADAM Governance OpEx'!$B$18 -> 3620000
A17: Marketing | B17: =B7*Assumptions!$B$92 -> 19548000 | C17: =C7*Assumptions!$B$92 -> 21893760 | D17: =D7*Assumptions!$B$92 -> 24521011 | E17: =E7*Assumptions!$B$92 -> 27463533 | F17: =F7*Assumptions!$B$92 -> 30759156
A18: G&A (excl ADAM/IT) | B18: =B7*Assumptions!$B$93 -> 15638400 | C18: =C7*Assumptions!$B$93 -> 17515008 | D18: =D7*Assumptions!$B$93 -> 19616809 | E18: =E7*Assumptions!$B$93 -> 21970826 | F18: =F7*Assumptions!$B$93 -> 24607325
A19: TOTAL OPERATING COSTS | B19: =SUM(B11:B18) -> 94674858 | C19: =SUM(C11:C18) -> 1.231124e+08 | D19: =SUM(D11:D18) -> 1.5496244e+08 | E19: =SUM(E11:E18) -> 1.9499913e+08 | F19: =SUM(F11:F18) -> 2.1879107e+08
A21: OPERATING INCOME (EBITDA proxy) | B21: =B7-B19 -> 1.0080514e+08 | C21: =C7-C19 -> 95825201 | D21: =D7-D19 -> 90247668 | E21: =E7-E19 -> 79636191 | F21: =F7-F19 -> 88800494
A22: Operating Margin % | B22: =B21/B7 -> 0.51568008 | C22: =C21/C7 -> 0.43768271 | D22: =D21/D7 -> 0.3680422 | E22: =E21/E7 -> 0.28997068 | F22: =F21/F7 -> 0.28869613
A24: ADAM/IT total cost per sub /mo (cash + amort blended) | B24: =(B12+B13+B14+B15+B16)/B3/12 -> 3.2469215 | C24: =(C12+C13+C14+C15+C16)/C3/12 -> 2.9903112 | D24: =(D12+D13+D14+D15+D16)/D3/12 -> 2.7611948 | E24: =(E12+E13+E14+E15+E16)/E3/12 -> 2.8155154 | F24: =(F12+F13+F14+F15+F16)/F3/12 -> 2.8362778
A26: MEMO: Year 1 CASH outlay (CapEx + full opex, ignoring amort) | B26: ='Hardware CapEx'!$E$50+'On-Prem OpEx'!$B$32+'CDN & Net Services'!$B$14+'ADAM Governance OpEx'!$B$18 -> 71396108

Sheet Pricing Scenarios
A1: Pricing Scenarios — Required ARPU vs Recommended Tier Map
A2: Tier | B2: A: Current Market | C2: B: Sovereign Conservative | D2: C: Recommended | E2: D: Sovereign Premium | F2: Notes
A3: Ad-supported | B3: 5.99 | C3: 4.99 | D3: 5.99 | E3: 6.99 | F3: Premium ad-load reduction at sovereign tier
A4: Basic SD | B4: 9.99 | C4: 8.99 | D4: 9.99 | E4: 11.99 | F4: Floor; minor uplift at premium scenario
A5: Standard HD | B5: 14.99 | C5: 13.99 | D5: 14.99 | E5: 16.99 | F5: Anchor; sensitive to competitor moves
A6: Premium UHD | B6: 19.99 | C6: 18.99 | D6: 19.99 | E6: 22.99 | F6: UHD + Dolby Vision + 4-stream
A7: Premium Plus | B7: 24.99 | C7: 24.99 | D7: 27.99 | E7: 32.99 | F7: Sovereign-bundled tier, new anchor
A8: Mix (Ad/Basic/Std/Prem/PP) | B8: 20/10/40/25/5 | C8: 20/10/40/25/5 | D8: 20/10/40/25/5 | E8: 15/8/40/27/10 | F8: PP scales in Premium scenario
A9: Blended ARPU (sub only) /mo | B9: =0.2*B3+0.1*B4+0.4*B5+0.25*B6+0.05*B7 -> 14.44 | C9: =0.2*C3+0.1*C4+0.4*C5+0.25*C6+0.05*C7 -> 13.49 | D9: =0.2*D3+0.1*D4+0.4*D5+0.25*D6+0.05*D7 -> 14.59 | E9: =0.15*E3+0.08*E4+0.4*E5+0.27*E6+0.1*E7 -> 18.31
A10: + Ad ARPU uplift (ad-tier × $8.50) | B10: =0.2*8.5 -> 1.7 | C10: =0.2*8.5 -> 1.7 | D10: =0.2*8.5 -> 1.7 | E10: =0.15*8.5 -> 1.275
A11: TOTAL BLENDED ARPU /sub /mo | B11: =B9+B10 -> 16.14 | C11: =C9+C10 -> 15.19 | D11: =D9+D10 -> 16.29 | E11: =E9+E10 -> 19.585
A13: Annual revenue (subs × ARPU × 12) | B13: =Assumptions!$B$4*B11*12 -> 193680000 | C13: =Assumptions!$B$4*C11*12 -> 1.8228e+08 | D13: =Assumptions!$B$4*D11*12 -> 195480000 | E13: =Assumptions!$B$4*E11*12 -> 2.3502e+08
A14: Annual all-in cost (run-rate, content + IT + ops) | B14: ='Consolidated TCO'!$B$15+B13*(Assumptions!$B$91/Assumptions!$B$90+Assumptions!$B$92+Assumptions!$B$93) -> 94161858 | C14: ='Consolidated TCO'!$B$15+C13*(Assumptions!$B$91/Assumptions!$B$90+Assumptions!$B$92+Assumptions!$B$93) -> 90912858 | D14: ='Consolidated TCO'!$B$15+D13*(Assumptions!$B$91/Assumptions!$B$90+Assumptions!$B$92+Assumptions!$B$93) -> 94674858 | E14: ='Consolidated TCO'!$B$15+E13*(Assumptions!$B$91/Assumptions!$B$90+Assumptions!$B$92+Assumptions!$B$93) -> 1.0594376e+08
A15: Operating margin | B15: =(B13-B14)/B13 -> 0.51382766 | C15: =(C13-C14)/C13 -> 0.50124611 | D15: =(D13-D14)/D13 -> 0.51568008 | E15: =(E13-E14)/E13 -> 0.54921386
A17: Required ARPU for 35% operating margin | B17: =('Consolidated TCO'!$B$15/(0.65-(Assumptions!$B$91/Assumptions!$B$90+Assumptions!$B$92+Assumptions!$B$93)))/Assumptions!$B$4/12 -> 8.8956754 | C17: (same — fixed structure) | D17: (same — fixed structure) | E17: (same — fixed structure) | F17: Floor pricing for sustainable 35% op margin

Sheet Competitive Bench
A1: Competitive Benchmark — Q1 2026 Streaming Pricing (US/EU)
A2: Service | B2: Ad-tier | C2: Basic | D2: Standard | E2: Premium | F2: UHD/Top | G2: Notes
A3: Netflix | B3: 6.99 | C3: — | D3: 17.99 | E3: — | F3: 24.99 | G3: No basic in US; ad-tier limited content
A4: Disney+ | B4: 7.99 | C4: — | D4: 13.99 | E4: — | F4: 20.99 | G4: Hulu bundle adds $3-5
A5: Max (HBO) | B5: 9.99 | C5: — | D5: 16.99 | E5: — | F5: 20.99 | G5: UHD only at top tier
A6: Paramount+ | B6: 7.99 | C6: — | D6: 12.99 | E6: — | F6: 14.99 | G6: Bundles with Showtime
A7: Apple TV+ | B7: — | C7: — | D7: — | E7: 9.99 | F7: — | G7: Single tier
A8: Prime Video | B8: 2.99 | C8: — | D8: 8.99 | E8: — | F8: 14.99 | G8: $2.99 add-on if Prime member
A9: Hulu | B9: 7.99 | C9: — | D9: 17.99 | E9: — | F9: 18.99 | G9: Live TV $76.99
A10: Mubi | B10: — | C10: — | D10: 14.99 | E10: — | F10: — | G10: Premium curated, single tier
A11: Peacock | B11: 7.99 | C11: — | D11: 13.99 | E11: — | F11: 13.99 | G11: NBCU bundles
A12: YouTube Premium | B12: — | C12: 13.99 | D12: — | E12: — | F12: — | G12: Music + ad-free YouTube
A13: MARKET MEDIAN | B13: =MEDIAN(B3:B12) -> 7.99 | C13: =MEDIAN(C3:C12) -> 13.99 | D13: =MEDIAN(D3:D12) -> 14.49 | E13: =MEDIAN(E3:E12) -> 9.99 | F13: =MEDIAN(F3:F12) -> 18.99 | G13: Median across competitive set excluding zeros where applicable
A14: NETSTREAMX (Recommended Scenario C) | B14: ='Pricing Scenarios'!D3 -> 5.99 | C14: ='Pricing Scenarios'!D4 -> 9.99 | D14: ='Pricing Scenarios'!D5 -> 14.99 | E14: ='Pricing Scenarios'!D6 -> 19.99 | F14: ='Pricing Scenarios'!D7 -> 27.99 | G14: Recommended sovereign-on-prem pricing

Sheet OnPrem vs MultiCloud
A1: Sovereign On-Prem vs Multi-Cloud Azure-Primary — Side-by-Side
A2: Cost Bucket | B2: On-Prem (this model) | C2: Multi-Cloud (v1 model) | D2: Δ (On-Prem − MC) | E2: Notes
A3: Annual run-rate (Year 1, amortized) | B3: ='Consolidated TCO'!$B$15 -> 38963058 | C3: 47500000 | D3: =B3-C3 -> -8536941.8 | E3: On-prem run-rate vs multi-cloud (Azure West Europe primary + AWS standby)
A4: Year 1 CASH outlay | B4: ='Consolidated TCO'!$B$8 -> 71396108 | C4: 47500000 | D4: =B4-C4 -> 23896108 | E4: On-prem requires upfront capital — multi-cloud is pay-as-you-go
A5: 5-year cumulative TCO | B5: ='Hardware CapEx'!$E$50+5*'On-Prem OpEx'!$B$32+5*'ADAM Governance OpEx'!$B$18+'CDN & Net Services'!$B$14*(1+1.12+1.12^2+1.12^3+1.12^4)+2*'Hardware CapEx'!$E$52 -> 2.1737433e+08 | C5: 260000000 | D5: =B5-C5 -> -42625673 | E5: 5-year cumulative — on-prem amortizes capex; multi-cloud has consumption growth
A6: FTE required (in-house) | B6: =Assumptions!$B$59 -> 39 | C6: 23 | D6: =B6-C6 -> 16 | E6: On-prem requires +16 FTE for DC ops, network, hardware lifecycle, ML ops
A7: Capacity-add lead time | B7: 12-16 weeks | C7: minutes-hours | D7: Major | E7: Hardware procurement vs cloud elasticity — sovereign trade-off
A8: Data egress to public cloud | B8: Zero (only encoded video segments) | C8: PII + telemetry + AI + content | D8: Sovereignty win | E8: DORA / NIS2 / EU AI Act posture: on-prem materially stronger
A9: Regulatory premium (insurance + audit) | B9: Lower (sovereign defensible) | C9: Higher (cross-border attestations) | D9: Insurance ~20% lower for sovereign | E9: AI-amplified D&O premiums favor on-prem if EU regulated
A10: Burst capacity for events | B10: Fixed (must over-provision) | C10: Elastic | D10: Risk: live-event peaks | E10: Recommendation: use cloud burst for live events (hybrid pattern)
A12: BREAK-EVEN ANALYSIS
A13: Years to recoup CapEx vs multi-cloud (assume on-prem opex ≤ multi-cloud) | B13: ='Hardware CapEx'!$E$50/MAX((47500000-('On-Prem OpEx'!$B$32+'CDN & Net Services'!$B$14+'ADAM Governance OpEx'!$B$18)),1) -> 2.4356152 | E13: CapEx ÷ annual savings vs multi-cloud — < 5y means on-prem wins economically

Sheet Recommendations
A1: Recommendations — Sustainable & Growth-Oriented Pricing Strategy
A3: HEADLINE
A4: For 1M subs on a fully sovereign on-prem ADAM substrate, the model shows a Year-1 CASH outlay near $74M (~$38M CapEx + ~$37M OpEx) and a normalized run-rate of ~$44–46M/year once CapEx is amortized. Versus the Azure-primary multi-cloud reference (~$47.5M run-rate), sovereign on-prem is approximately TCO-neutral over 5 years and net-cheaper from Year 4 onward — but it consumes capital, consumes lead-time flexibility, and consumes 16 additional FTEs. The trade is sovereignty + regulatory posture + operational independence in exchange for capital intensity.
A6: PRICING RECOMMENDATION (Sovereign-Bundled Anchor)
A7: Adopt a 5-tier structure with a NEW 'Premium Plus' anchor at $27.99 that bundles UHD + downloads + the sovereignty value proposition (EU-resident data, EU-resident inference, no-undisclosed-AI guarantee). Recommended tiers: Ad-supported $5.99 / Basic SD $9.99 / Standard HD $14.99 / Premium UHD $19.99 / Premium Plus $27.99. Blended ARPU comes out at ~$15.00 sub-only + ~$1.70 ad-uplift = ~$16.70/sub/mo.
A9: WHY THE NEW 'PREMIUM PLUS' ANCHOR
A10: 1) Captures the household that values data sovereignty (EU professional class, regulated industries, creator economy users producing IP-sensitive material). 2) Lifts blended ARPU by ~$3 vs Standard-only anchor without alienating the price-sensitive base. 3) Justifies the on-prem CapEx as a differentiator, not an operating tax. 4) Creates ad-free + extended-catalog combo that competes against Mubi/Apple TV+ at the high end and Netflix Premium at the low end.
A12: COMPETITIVE POSITIONING
A13: Recommended pricing puts NetStreamX BELOW Netflix on Standard ($14.99 vs $17.99) and Premium ($19.99 vs $24.99), at parity with Disney+ on Premium, and ABOVE the market median on Premium Plus ($27.99 vs $20-21 median). The premium positioning is justifiable because (a) sovereignty is a credible differentiator no incumbent matches, (b) UHD + Dolby Vision + 4-stream + downloads is a complete bundle, (c) on-prem ADAM means content recommendations explainable per EU AI Act.
A15: SOVEREIGNTY AS A PRODUCT
A16: Treat the on-prem investment as a product feature, not back-office spend. Marketing language: 'Your watching never leaves Europe.' 'Recommendations you can audit.' 'No AI surprise.' Pair with a trust badge (Flight Recorder receipts available on request — replay-able evidence trail). This converts a CapEx burden into a brand premium.
A18: HYBRID PATTERN FOR LIVE EVENTS
... A34: Pursue sovereign on-prem if AND ONLY IF: (a) you serve >800K subscribers in regulated EU markets AND (b) you can fund $40M of CapEx without dilution AND (c) you can hire 41 FTEs sustainably AND (d) sovereignty is a marketable feature for your audience. NetStreamX meets all four — making this recommendation actionable. If any test fails, the multi-cloud Azure-primary model (companion file) is the better choice.
