Workbook

Sheet README
A1: ADAM + NetStreamX — Cloud Cost & Revenue Model v1.1
A3: SCENARIO
A4: Full production deployment of the ADAM framework (CORE Engine, 81-Agent Mesh, BOSS Scoring, Flight Recorder, Governance Plane) on top of the NetStreamX streaming workload — scaled to 1,000,000 subscribers and a 100,000-title UHD catalog (average 2-hour films in H.265/AV1).
A6: DEPLOYMENT ARCHITECTURE
A7: Azure West Europe PRIMARY (active) + AWS eu-west-1 STANDBY (30% warm) as per ADAM_MultiCloud_Azure_Primary_AWS_Standby_v2.0.drawio. Active/active global edge; cross-cloud fabric via Megaport/Equinix; full services plane on both sides (Identity, Compute, AI/ML, Data, Messaging, Security).
A9: WHAT'S IN / WHAT'S OUT
A10: IN: All Azure+AWS infrastructure, data, networking, AI/LLM tokens, observability, identity, origin+CDN, transcoding, recommendations, billing stack, DRM, and the ADAM governance overlay (Governor agents, CORE graph, Flight Recorder, BOSS, Policy Plane, Human Interface). OUT: Content licensing / original production (tracked as a separate P&L line), marketing, labour & G&A, on-prem Azure Local ($62K-$206K one-time is noted but not carried in OpEx).
A12: PRICING BASIS
A13: Azure and AWS April 2026 published list prices (West Europe / eu-west-1), before Reserved Instance or Savings Plan commitments. Scenario sheets apply a realistic 25% blended RI/SP discount ('Current Pricing — Committed') and test a 'Future Pricing' scenario reflecting typical 8-12% annual unit-price deflation in compute+storage, partially offset by AI inference price drops.
A15: WORKBOOK MAP
A16: 1. Assumptions — every knob in one place (edit blue cells only) 2. Workload Sizing — derives traffic PB/mo, storage PB, compute vCPU/GPU from subscriber + catalog figures 3. Azure Primary Cost — ~35 line items across 8 service families 4. AWS Standby Cost — 30% warm shape mirrored 5. ADAM Governance OpEx — overlay cost attributable to ADAM itself (separable from streaming) 6. Consolidated OpEx — totals, 1/3/5-year, unit cost per subscriber 7. Revenue Model — four-tier pricing, mix, churn, growth 8. 5-Year P&L — cost vs revenue, margin, break-even 9. Pricing Scenarios — Current list / Current committed / Future (3y) / Future (5y) 10. Competitive Bench — Netflix, Disney+, Max, Paramount+, Apple TV+ on ARPU & margin 11. Recommendations — pricing per customer to sustain and grow the business
A18: MODEL CONVENTIONS
... A25: Michael — ADAM author. Model version 1.0. Built April 2026.

Sheet Assumptions
A1: Assumptions — Single Source of Truth (edit blue cells only)
A2: Assumption | B2: Value | C2: Units | D2: Notes / Source
A3: SUBSCRIBER & CATALOG
A4: Subscribers (paid, launch) | B4: 1000000 | C4: subs | D4: User request.
A5: Active-subscriber ratio (weekly) | B5: 0.65 | C5: % | D5: Industry: Netflix ~70%, Max ~60%.
A6: Hours streamed / active sub / day | B6: 2.1 | C6: hrs | D6: Netflix avg 2 hrs; Max 1.7 hrs.
A7: Video catalog (titles) | B7: 100000 | C7: titles | D7: User request.
A8: Average title length | B8: 2 | C8: hrs | D8: User request (UHD film).
A9: Subscriber growth Y-o-Y | B9: 0.12 | C9: % | D9: Aggressive growth tier assumption (industry 6-10%).
A10: Annual gross churn | B10: 0.3 | C10: % | D10: SVOD average 28-35%; premium lower.
A11: ENCODING & BITRATE
A12: UHD delivered bitrate | B12: 15 | C12: Mbps | D12: AV1/HEVC 2026; was 25 Mbps on H.264.
A13: HD delivered bitrate | B13: 5 | C13: Mbps | D13: AV1 720p/1080p.
A14: SD/Mobile delivered bitrate | B14: 1.5 | C14: Mbps | D14: AV1 480p / mobile.
A15: % of viewing at UHD | B15: 0.3 | C15: % | D15: 2026 mix; growing 3pp/yr.
A16: % of viewing at HD | B16: 0.5 | C16: %
A17: % of viewing at SD/Mobile | B17: 0.2 | C17: %
A18: Encoding cost per source hour | B18: 42 | C18: $/hr | D18: AWS Elemental MediaConvert: $0.45/min UHD HDR ~ $27/hr UHD + 15/hr for HD/SD ladder. Blended.
A19: Catalog refresh (new titles / yr) | B19: 8000 | C19: titles | D19: 8% new originals + licensed refresh / yr.
A20: ABR ladder renditions per title | B20: 10 | C20: renditions | D20: UHD + 2xHD + 3xSD + 4xmobile.
A21: Storage per source UHD hour (master) | B21: 22 | C21: GB | D21: ProRes-adjacent 4K HDR master.
A22: Storage per finished title (all renditions) | B22: 55 | C22: GB | D22: Full ABR ladder, distribution copies.
A23: NETWORK / CDN
A24: Blended CDN price (negotiated) | B24: 0.012 | C24: $/GB | D24: At 100+ PB/mo, Akamai/Fastly/Cloudflare deals land $0.008-$0.015. NOT CloudFront list.
A25: On-net / peering share | B25: 0.25 | C25: % | D25: ISP peering offsets CDN at large scale (Netflix OpenConnect ~95%; new entrant ~25%).
A26: Origin-to-CDN egress ratio | B26: 1.08 | C26: x | D26: CDN cache miss + re-fill factor vs. subscriber egress.
A27: AWS ExpressRoute / Direct Connect (each) | B27: 8000 | C27: $/mo | D27: 10 Gbps Premium pair.
A28: Megaport / Equinix cross-cloud fabric | B28: 6500 | C28: $/mo | D28: 10G cross-connect pair (redundant).
A29: ADAM GOVERNANCE OVERLAY
A30: 81 agents decisions/day | B30: 20000000 | C30: decisions | D30: 81 agents × ~250K routine + 5K heavy decisions/day/agent.
A31: Avg tokens per decision (input) | B31: 2400 | C31: tokens | D31: Includes policy context, CORE graph snippet, BOSS prompt.
A32: Avg tokens per decision (output) | B32: 420 | C32: tokens | D32: Intent Object + justification.
A33: % routed to small model (GPT-4o-mini) | B33: 0.85 | C33: % | D33: Cost-optimized routing per agent role.
A34: % routed to reasoning model (GPT-4o) | B34: 0.15 | C34: % | D34: Governor + AI-Native agents.
A35: GPT-4o-mini input price | B35: 0.15 | C35: $/M tok | D35: Azure OpenAI Apr 2026 list.
A36: GPT-4o-mini output price | B36: 0.6 | C36: $/M tok | D36: Azure OpenAI Apr 2026 list.
A37: GPT-4o input price | B37: 2.5 | C37: $/M tok | D37: Azure OpenAI Apr 2026 list.
A38: GPT-4o output price | B38: 10 | C38: $/M tok | D38: Azure OpenAI Apr 2026 list.
A39: Flight Recorder retention | B39: 7 | C39: years | D39: EU AI Act Art.12/DORA Art.28.
A40: Intent events per day | B40: 300000000 | C40: events | D40: Every subscriber action + every agent action.
...

Sheet Workload Sizing
A1: Workload Sizing — derives traffic / storage / compute from assumptions
A2: Metric | B2: Value | C2: Units | D2: Formula / Notes
A3: STREAMING TRAFFIC (per month)
A4: Weighted avg delivered bitrate | B4: =(Assumptions!$B$12*Assumptions!$B$15+Assumptions!$B$13*Assumptions!$B$16+Assumptions!$B$14*Assumptions!$B$17) -> 7.3 | C4: Mbps | D4: UHD×%UHD + HD×%HD + SD×%SD
A5: Daily active subscribers | B5: =Assumptions!$B$4*Assumptions!$B$5 -> 650000 | C5: subs | D5: Approx DAU (weekly active ≈ daily active × 7/7 for heavy streamers)
A6: Monthly viewing hours (total) | B6: =B5*Assumptions!$B$6*30 -> 40950000 | C6: hrs/mo | D6: Formula: DAU × hrs/day × 30
A7: Monthly subscriber egress | B7: =(B6*B4*3600)/8/1024/1024/1024 -> 125.28221 | C7: PB | D7: Formula: hrs × Mbps × 3600s / 8 bits / 1024^3 (MB→PB binary)
A8: CDN cache-fill traffic (origin→edge) | B8: =B7*Assumptions!$B$26-B7 -> 10.022577 | C8: PB | D8: Incremental PB vs user egress — origin→CDN refills
A9: Billable CDN egress (post-peering) | B9: =B7*(1-Assumptions!$B$25) -> 93.961658 | C9: PB | D9: What you actually pay CDN providers for
A10: STORAGE FOOTPRINT
A11: Total finished library (all renditions) | B11: =Assumptions!$B$7*Assumptions!$B$22/1024/1024 -> 5.2452087 | C11: PB | D11: Formula: titles × GB/title / 1,048,576
A12: Master source library | B12: =Assumptions!$B$7*Assumptions!$B$8*Assumptions!$B$21/1024/1024 -> 4.196167 | C12: PB | D12: Formula: titles × hrs × GB/hr / 1,048,576
A13: Archive / cold tier (10-year vault) | B13: =B12*3 -> 12.588501 | C13: PB | D13: Master copies × 3 (geo-redundant archive)
A14: Flight Recorder evidence (7-yr WORM) | B14: =(Assumptions!$B$40*Assumptions!$B$41*365*7)/1024/1024/1024/1024/1024 -> 1.2254198 | C14: PB | D14: Formula: events/day × bytes × 365 × 7 / 1024^5 (bytes→PB binary)
A15: ADAM AI / LLM TOKENS
A16: Decisions per month | B16: =Assumptions!$B$30*30 -> 600000000 | C16: decisions
A17: Input tokens / month | B17: =B16*Assumptions!$B$31 -> 1440000000000 | C17: tokens/mo
A18: Output tokens / month | B18: =B16*Assumptions!$B$32 -> 252000000000 | C18: tokens/mo
A19: COMPUTE — ADAM reference sizing (from book)
A20: AKS primary vCPU (system+governance+workgroup+twin) | B20: =3180 -> 3180 | C20: vCPU | D20: From ADAM Reference Architecture (3,180 vCPU / 12,720 GB RAM / 42 GPU).
A21: GPU (H100/A100 equivalents) | B21: =42 -> 42 | C21: vCPU | D21: Digital Twin + Governor inference pool.
A22: EKS standby vCPU (30% warm) | B22: =B20*0.3 -> 954 | C22: vCPU | D22: 30% warm shape per DR policy.
A23: TRANSCODING / ENCODING
A24: New encoding hours / year | B24: =Assumptions!$B$19*Assumptions!$B$8 -> 16000 | C24: hrs/mo | D24: Formula: new titles/yr × hrs (annual figure)
A25: New encoding hours / month | B25: =B24/12 -> 1333.3333 | C25: hrs/mo

Sheet Azure Primary
A1: Azure Primary Region (West Europe) — Monthly Cost Build-Up
A2: Service | B2: Configuration | C2: Unit | D2: Unit Price ($) | E2: Quantity | F2: Monthly Cost ($) | G2: Annual Cost ($) | H2: Notes / Source
A3: GLOBAL EDGE — Traffic Manager, Front Door, WAF, CloudFront
A4: Azure Traffic Manager | B4: Priority + weighted GSLB (global) | C4: per 1M queries | D4: 0.54 | E4: =100*30 -> 3000 | F4: =D4*E4 -> 1620 | G4: =F4*12 -> 19440 | H4: Azure list Apr 2026 — $0.54 per 1M DNS queries; 100M/day baseline × 30 days × 1k (queries unit is M).
A5: Azure Front Door Premium | B5: Standard tier; global anycast + WAF | C5: per GB | D5: 0.0185 | E5: =(('Workload Sizing'!B9*1024*1024)*0.15) -> 14778891 | F5: =D5*E5 -> 273409.48 | G5: =F5*12 -> 3280913.8 | H5: 15% of user egress served by Front Door; balance by external CDN. Azure AFD Prem: $0.019/GB.
A6: Azure Front Door requests | B6: Standard tier | C6: per 1M req | D6: 0.9 | E6: =90000 -> 90000 | F6: =D6*E6 -> 81000 | G6: =F6*12 -> 972000 | H6: 90B requests/mo = 90,000 M. API+manifest+segment.
A7: Azure WAF rule processing | B7: WAF Premium | C7: per 1M req | D7: 0.6 | E7: =90000 -> 90000 | F7: =D7*E7 -> 54000 | G7: =F7*12 -> 648000 | H7: WAF incl. bot/managed rulesets.
A8: NETWORK FABRIC — ExpressRoute, Peering, NAT
A9: ExpressRoute 10Gbps Premium | B9: Primary pair (redundant) | C9: circuit-pair/mo | D9: 8000 | E9: =1 -> 1 | F9: =D9*E9 -> 8000 | G9: =F9*12 -> 96000 | H9: 10 Gbps Premium unlimited global reach; $4-8K/mo each.
A10: Megaport cross-cloud fabric | B10: 10G redundant | C10: x-conn-pair/mo | D10: 6500 | E10: =1 -> 1 | F10: =D10*E10 -> 6500 | G10: =F10*12 -> 78000 | H10: To AWS eu-west-1 for cross-cloud sync.
A11: VNet inter-region replication | B11: Paired region geo-redundancy | C11: per GB | D11: 0.02 | E11: =50000 -> 50000 | F11: =D11*E11 -> 1000 | G11: =F11*12 -> 12000 | H11: 50 TB/mo cross-region (Cosmos geo, Blob RA-GRS).
A12: NAT Gateway | B12: 3 AZ | C12: hour | D12: 0.045 | E12: =3*730 -> 2190 | F12: =D12*E12 -> 98.55 | G12: =F12*12 -> 1182.6 | H12: 3 gateways × 730 hr.
A13: IDENTITY & ACCESS — Entra ID, PIM, Defender
A14: Microsoft Entra ID P2 | B14: Employees + partners | C14: user/mo | D14: 9 | E14: =800 -> 800 | F14: =D14*E14 -> 7200 | G14: =F14*12 -> 86400 | H14: 800 internal + partner accounts.
A15: Entra External ID (customer) | B15: B2C authn, 1M MAU | C15: per MAU | D15: 0.00325 | E15: =(Assumptions!$B$4*Assumptions!$B$5) -> 650000 | F15: =D15*E15 -> 2112.5 | G15: =F15*12 -> 25350 | H15: Weekly active subs as MAU. $0.00325/MAU after 50K free.
A16: Key Vault Premium (HSM) | B16: Managed HSM | C16: HSM/mo | D16: 3195 | E16: =2 -> 2 | F16: =D16*E16 -> 6390 | G16: =F16*12 -> 76680 | H16: 2 HSM pools (multi-AZ).
A17: Key Vault operations | B17: HSM key ops | C17: per 10K ops | D17: 0.15 | E17: =5000000/10000 -> 500 | F17: =D17*E17 -> 75 | G17: =F17*12 -> 900 | H17: 5B ops/mo (intent signing).
A18: Confidential Ledger | B18: 3-replica transparency ledger | C18: per write | D18: 5e-06 | E18: =300000000*30 -> 9000000000 | F18: =D18*E18 -> 45000 | G18: =F18*12 -> 540000 | H18: 9B writes/mo from Flight Recorder attestation.
A19: COMPUTE — AKS, Functions, App Services
A20: AKS — E32s v5 (Governance/Twin) | B20: 6× E32s v5 × 730h | C20: node-mo | D20: 1679 | E20: =6 -> 6 | F20: =D20*E20 -> 10074 | G20: =F20*12 -> 120888 | H20: E32s v5 = $2.30/hr × 730 = $1,679/mo. Governance plane.
A21: AKS — D16s v5 (Work-Group mesh) | B21: 40× D16s v5 × 730h | C21: node-mo | D21: 583 | E21: =40 -> 40 | F21: =D21*E21 -> 23320 | G21: =F21*12 -> 279840 | H21: D16s v5 = $0.80/hr × 730 = $583/mo. 81 agents workgroup.
A22: AKS — A100 GPU pool (Governor) | B22: 5× NC24ads A100 v4 × 730h | C22: node-mo | D22: 5489 | E22: =5 -> 5 | F22: =D22*E22 -> 27445 | G22: =F22*12 -> 329340 | H22: NC24ads A100 v4 = $7.52/hr × 730 = $5,489/mo.
A23: AKS — H100 GPU pool (Digital Twin) | B23: 8× NC48ads H100 v5 × 730h | C23: node-mo | D23: 17520 | E23: =8 -> 8 | F23: =D23*E23 -> 140160 | G23: =F23*12 -> 1681920 | H23: NC48ads H100 v5 $24/hr × 730 = $17,520/mo.
A24: Azure Functions (Premium) | B24: EP3 × 4 plans | C24: plan-mo | D24: 1029 | E24: =4 -> 4 | F24: =D24*E24 -> 4116 | G24: =F24*12 -> 49392 | H24: Intent Object pipeline stage handlers.
A25: App Service Premium v3 | B25: P2v3 × 8 (web frontends) | C25: plan-mo | D25: 280 | E25: =8 -> 8 | F25: =D25*E25 -> 2240 | G25: =F25*12 -> 26880 | H25: Portal, admin, hi-explain UI.
A26: AI / ML — Azure OpenAI, AI Search, ML
A27: Azure OpenAI GPT-4o-mini input | B27: 85% routing | C27: per 1M tok | D27: 0.15 | E27: =('Workload Sizing'!B17/1000000)*0.85 -> 1224000 | F27: =D27*E27 -> 183600 | G27: =F27*12 -> 2203200 | H27: In millions.
A28: Azure OpenAI GPT-4o-mini output | B28: 85% routing | C28: per 1M tok | D28: 0.6 | E28: =('Workload Sizing'!B18/1000000)*0.85 -> 214200 | F28: =D28*E28 -> 128520 | G28: =F28*12 -> 1542240
A29: Azure OpenAI GPT-4o input | B29: 15% routing (reasoning) | C29: per 1M tok | D29: 2.5 | E29: =('Workload Sizing'!B17/1000000)*0.15 -> 216000 | F29: =D29*E29 -> 540000 | G29: =F29*12 -> 6480000
A30: Azure OpenAI GPT-4o output | B30: 15% routing | C30: per 1M tok | D30: 10 | E30: =('Workload Sizing'!B18/1000000)*0.15 -> 37800 | F30: =D30*E30 -> 378000 | G30: =F30*12 -> 4536000
A31: Azure OpenAI embeddings | B31: text-embedding-3-large | C31: per 1M tok | D31: 0.13 | E31: =500 -> 500 | F31: =D31*E31 -> 65 | G31: =F31*12 -> 780 | H31: 500M tokens/mo across CORE/RAG indexing.
A32: Azure AI Search — Standard S3 | B32: Vector + semantic, 3 replicas | C32: unit-mo | D32: 3900 | E32: =3 -> 3 | F32: =D32*E32 -> 11700 | G32: =F32*12 -> 140400 | H32: S3 unit for large RAG / CORE graph annotations.
A33: Azure ML compute (training) | B33: NC24ads A100 v4 × 500 hr/mo | C33: hour | D33: 7.52 | E33: =500 -> 500 | F33: =D33*E33 -> 3760 | G33: =F33*12 -> 45120 | H33: Twin model retraining, recommender.
A34: DATA — Cosmos, ADX, Blob, SQL
A35: Cosmos DB Gremlin (CORE graph) | B35: Autoscale 300K RU/s, 2-region | C35: RU-hr | D35: 0.00016 | E35: =300000*0.1*730*2 -> 43800000 | F35: =D35*E35 -> 7008 | G35: =F35*12 -> 84096 | H35: Gremlin autoscale $0.0016/100 RU/s × 10% avg utilization × 2 regions.
A36: Cosmos DB storage | B36: Graph data | C36: per GB-mo | D36: 0.25 | E36: =8000 -> 8000 | F36: =D36*E36 -> 2000 | G36: =F36*12 -> 24000 | H36: 8 TB graph data (CORE DNA × 4 years of evolution).
A37: Azure Data Explorer (Flight Rec hot) | B37: 4× D14v2 + shuffle | C37: hour | D37: 4.3 | E37: =4*730 -> 2920 | F37: =D37*E37 -> 12556 | G37: =F37*12 -> 150672 | H37: Hot-tier for last 90 days of Flight Recorder events.
A38: Blob Storage Hot (Flight Recorder WORM) | B38: ZRS, immutability | C38: per GB-mo | D38: 0.0198 | E38: =('Workload Sizing'!B14*1024*1024)*0.1 -> 128494.58 | F38: =D38*E38 -> 2544.1926 | G38: =F38*12 -> 30530.311 | H38: 10% of 7yr evidence in hot.
A39: Blob Storage Cool (Flight Recorder WORM) | B39: ZRS immutable | C39: per GB-mo | D39: 0.01 | E39: =('Workload Sizing'!B14*1024*1024)*0.3 -> 385483.73 | F39: =D39*E39 -> 3854.8373 | G39: =F39*12 -> 46258.047 | H39: 30% in cool.
A40: Blob Storage Archive (WORM) | B40: 7-yr compliance | C40: per GB-mo | D40: 0.00099 | E40: =('Workload Sizing'!B14*1024*1024)*0.6 -> 770967.45 | F40: =D40*E40 -> 763.25778 | G40: =F40*12 -> 9159.0934 | H40: 60% in archive.
...

Sheet AWS Standby
A1: AWS Standby Region (eu-west-1) — 30% warm DR shape
A2: Service | B2: Configuration | C2: Unit | D2: Unit Price ($) | E2: Quantity | F2: Monthly Cost ($) | G2: Annual Cost ($) | H2: Notes / Source
A3: EDGE — CloudFront + Global Accelerator + Route 53 + WAFv2
A4: AWS CloudFront (bulk egress) | B4: Primary CDN for streaming | C4: per GB | D4: 0.012 | E4: =('Workload Sizing'!B9*1024*1024)*0.85 -> 83747049 | F4: =D4*E4 -> 1004964.6 | G4: =F4*12 -> 12059575 | H4: 85% of billable CDN egress routed via CloudFront (negotiated rate).
A5: CloudFront requests (HTTPS) | B5: Manifest + segment | C5: per 10K | D5: 0.01 | E5: =9000000 -> 9000000 | F5: =D5*E5 -> 90000 | G5: =F5*12 -> 1080000 | H5: 90B HTTPS requests/mo / 10K unit.
A6: AWS WAFv2 | B6: CloudFront WebACL | C6: per 1M req | D6: 0.6 | E6: =90000 -> 90000 | F6: =D6*E6 -> 54000 | G6: =F6*12 -> 648000
A7: AWS Global Accelerator | B7: Anycast IP failover | C7: accelerator-mo | D7: 18 | E7: =2 -> 2 | F7: =D7*E7 -> 36 | G7: =F7*12 -> 432 | H7: 2 accelerators.
A8: Route 53 — Hosted Zone | B8: Health-checked DNS | C8: zone-mo | D8: 0.5 | E8: =12 -> 12 | F8: =D8*E8 -> 6 | G8: =F8*12 -> 72 | H8: 12 zones.
A9: Route 53 queries | B9: Global | C9: per 1M q | D9: 0.4 | E9: =4500 -> 4500 | F9: =D9*E9 -> 1800 | G9: =F9*12 -> 21600 | H9: 4.5B queries/mo.
A10: IDENTITY & KEYS — IAM, IdC, Cognito, CloudHSM
A11: CloudHSM | B11: 2× cluster | C11: HSM-hour | D11: 1.45 | E11: =2*730 -> 1460 | F11: =D11*E11 -> 2117 | G11: =F11*12 -> 25404 | H11: FIPS 140-2 L3 dedicated.
A12: AWS IAM Identity Center (SSO) | B12: Free-tier — N/A | C12: included | D12: 0 | E12: =0 -> 0 | F12: =D12*E12 -> 0 | G12: =F12*12 -> 0 | H12: IdC is free.
A13: Amazon Cognito | B13: Customer identity, 10% active failover | C13: per MAU | D13: 0.00275 | E13: =(Assumptions!$B$4*0.1) -> 100000 | F13: =D13*E13 -> 275 | G13: =F13*12 -> 3300 | H13: 10% MAU as failover.
A14: COMPUTE — EKS + Lambda + App Runner
A15: EKS cluster fees | B15: 2× clusters | C15: cluster-mo | D15: 73 | E15: =2 -> 2 | F15: =D15*E15 -> 146 | G15: =F15*12 -> 1752 | H15: $0.10/hr × 2 × 730.
A16: EKS — m5.4xlarge (general) | B16: 20× × 730h (30% warm) | C16: node-mo | D16: 557 | E16: =20 -> 20 | F16: =D16*E16 -> 11140 | G16: =F16*12 -> 133680 | H16: m5.4xlarge EU-West-1 $0.764/hr × 730.
A17: EKS — c5.9xlarge (compute tier) | B17: 10× × 730h | C17: node-mo | D17: 1249 | E17: =10 -> 10 | F17: =D17*E17 -> 12490 | G17: =F17*12 -> 149880 | H17: c5.9xlarge $1.71/hr × 730.
A18: EKS — p4d.24xlarge (GPU standby) | B18: 2× × 730h | C18: node-mo | D18: 23914 | E18: =2 -> 2 | F18: =D18*E18 -> 47828 | G18: =F18*12 -> 573936 | H18: 8×A100 GPU node for Governor failover.
A19: AWS Lambda | B19: Function handlers | C19: per 1M req | D19: 0.2 | E19: =2000 -> 2000 | F19: =D19*E19 -> 400 | G19: =F19*12 -> 4800 | H19: 2B invocations/mo.
A20: AWS Fargate | B20: Fallback container runtime | C20: vCPU-hr | D20: 0.04048 | E20: =500*730 -> 365000 | F20: =D20*E20 -> 14775.2 | G20: =F20*12 -> 177302.4
A21: Application Load Balancer | B21: 4× multi-AZ | C21: LCU-hr | D21: 0.008 | E21: =4*730*100 -> 292000 | F21: =D21*E21 -> 2336 | G21: =F21*12 -> 28032
A22: AI/ML — Bedrock, Kendra, SageMaker
A23: AWS Bedrock — Claude Haiku (standby) | B23: Small model 30% shadow | C23: per 1M tok in | D23: 0.25 | E23: =('Workload Sizing'!B17/1000000)*0.3*0.85 -> 367200 | F23: =D23*E23 -> 91800 | G23: =F23*12 -> 1101600 | H23: 30% shadow traffic to AWS for DR validation.
A24: AWS Bedrock — Claude Haiku output | C24: per 1M tok out | D24: 1.25 | E24: =('Workload Sizing'!B18/1000000)*0.3*0.85 -> 64260 | F24: =D24*E24 -> 80325 | G24: =F24*12 -> 963900
A25: AWS Bedrock — Claude Sonnet (standby) | B25: Large model 30% shadow | C25: per 1M tok in | D25: 3 | E25: =('Workload Sizing'!B17/1000000)*0.3*0.15 -> 64800 | F25: =D25*E25 -> 194400 | G25: =F25*12 -> 2332800
A26: AWS Bedrock — Claude Sonnet output | C26: per 1M tok out | D26: 15 | E26: =('Workload Sizing'!B18/1000000)*0.3*0.15 -> 11340 | F26: =D26*E26 -> 170100 | G26: =F26*12 -> 2041200
A27: Amazon Kendra — Enterprise | B27: Fallback RAG | C27: index-mo | D27: 1008 | E27: =2 -> 2 | F27: =D27*E27 -> 2016 | G27: =F27*12 -> 24192 | H27: $1.40/hr × 730 per index.
A28: SageMaker endpoints (recommender) | B28: ml.g5.4xlarge × 4 | C28: node-mo | D28: 1616 | E28: =4 -> 4 | F28: =D28*E28 -> 6464 | G28: =F28*12 -> 77568 | H28: GPU endpoints for recommender failover.
A29: DATA — Neptune + Timestream + S3 Object Lock + QLDB
A30: Neptune — db.r5.8xlarge | B30: CORE graph replica | C30: node-mo | D30: 4759 | E30: =3 -> 3 | F30: =D30*E30 -> 14277 | G30: =F30*12 -> 171324 | H30: 3 readers.
A31: Neptune storage | C31: per GB-mo | D31: 0.1 | E31: =8000 -> 8000 | F31: =D31*E31 -> 800 | G31: =F31*12 -> 9600
A32: Amazon Timestream — memory store | B32: Flight Recorder hot replica | C32: per GB-mo | D32: 0.036 | E32: =5000 -> 5000 | F32: =D32*E32 -> 180 | G32: =F32*12 -> 2160 | H32: 5 TB hot tier.
A33: Amazon Timestream — magnetic store | C33: per GB-mo | D33: 0.03 | E33: =100000 -> 100000 | F33: =D33*E33 -> 3000 | G33: =F33*12 -> 36000 | H33: 100 TB magnetic.
A34: S3 Standard — video library replica | B34: Geo-redundant, 30% warm | C34: per GB-mo | D34: 0.023 | E34: =('Workload Sizing'!B11*1024*1024)*0.3 -> 1650000 | F34: =D34*E34 -> 37950 | G34: =F34*12 -> 455400 | H34: 30% warm replica.
A35: S3 Intelligent-Tiering — evidence | B35: Flight Recorder backup | C35: per GB-mo | D35: 0.0125 | E35: =('Workload Sizing'!B14*1024*1024)*0.3 -> 385483.73 | F35: =D35*E35 -> 4818.5466 | G35: =F35*12 -> 57822.559 | H35: 30% replicated.
A36: S3 Glacier Deep Archive — masters | B36: 10yr vault mirror | C36: per GB-mo | D36: 0.00099 | E36: =('Workload Sizing'!B12*1024*1024) -> 4400000 | F36: =D36*E36 -> 4356 | G36: =F36*12 -> 52272 | H36: Full master mirror.
A37: QLDB — ledger | B37: Crypto ledger replica | C37: per million writes | D37: 3.75 | E37: =900 -> 900 | F37: =D37*E37 -> 3375 | G37: =F37*12 -> 40500 | H37: 900M writes/mo (30% shadow).
A38: MESSAGING — MSK, SQS, EventBridge, Step Functions
A39: MSK — m5.4xlarge cluster | B39: MirrorMaker 2 from Event Hubs | C39: broker-mo | D39: 1249 | E39: =6 -> 6 | F39: =D39*E39 -> 7494 | G39: =F39*12 -> 89928 | H39: 6 brokers.
A40: SQS FIFO | B40: Transactional queues | C40: per 1M req | D40: 0.5 | E40: =8000 -> 8000 | F40: =D40*E40 -> 4000 | G40: =F40*12 -> 48000
...

Sheet ADAM Governance OpEx
A1: ADAM Governance Overlay — OpEx attributable to ADAM alone
A2: Line Item | B2: Monthly ($) | C2: Annual ($) | D2: % of Total | E2: Notes
A3: Azure OpenAI GPT-4o-mini (85% routing) | B3: =('Workload Sizing'!B17/1000000)*0.85*Assumptions!$B$35+('Workload Sizing'!B18/1000000)*0.85*Assumptions!$B$36 -> 312120 | C3: =B3*12 -> 3745440 | D3: =B3/$B$20 -> 0.11965221 | E3: Routine agent decisions (85% of 20M decisions/day)
A4: Azure OpenAI GPT-4o (15% routing) | B4: =('Workload Sizing'!B17/1000000)*0.15*Assumptions!$B$37+('Workload Sizing'!B18/1000000)*0.15*Assumptions!$B$38 -> 918000 | C4: =B4*12 -> 11016000 | D4: =B4/$B$20 -> 0.35191826 | E4: Governor + AI-Native reasoning
A5: AWS Bedrock shadow (30% DR validation) | B5: =('Workload Sizing'!B17/1000000)*0.3*0.85*0.25+('Workload Sizing'!B18/1000000)*0.3*0.85*1.25+('Workload Sizing'!B17/1000000)*0.3*0.15*3+('Workload Sizing'!B18/1000000)*0.3*0.15*15 -> 536625 | C5: =B5*12 -> 6439500 | D5: =B5/$B$20 -> 0.20571692 | E5: Claude Haiku+Sonnet on Bedrock, 30% shadow for DR & model diversity
A6: AKS Governance Plane (E32s v5 × 6 + A100 × 5) | B6: =6*1679+5*5489 -> 37519 | C6: =B6*12 -> 450228 | D6: =B6/$B$20 -> 0.01438303 | E6: Governance pool + Governor GPU
A7: AKS Agent Mesh (D16s v5 × 40, 81 agents) | B7: =40*583 -> 23320 | C7: =B7*12 -> 279840 | D7: =B7/$B$20 -> 0.0089397972 | E7: Work-group agent pods
A8: AKS Digital Twin GPU pool (H100 × 8) | B8: =8*17520 -> 140160 | C8: =B8*12 -> 1681920 | D8: =B8/$B$20 -> 0.053730788 | E8: Enterprise/Ops/Economic/Risk twins
A9: Cosmos DB Gremlin (CORE graph) | B9: =300000*0.1*730*2*0.00016 + 8000*0.25 -> 9008 | C9: =B9*12 -> 108096 | D9: =B9/$B$20 -> 0.0034532459 | E9: CORE DNA graph database (autoscale)
A10: Azure Data Explorer (Flight Recorder hot) | B10: =4*730*4.3 -> 12556 | C10: =B10*12 -> 150672 | D10: =B10/$B$20 -> 0.0048133831 | E10: Hot-tier query cluster for Flight Recorder
A11: Blob Storage — Flight Recorder (WORM 7yr) | B11: =('Workload Sizing'!B14*1024*1024)*(0.1*0.0198+0.3*0.01+0.6*0.00099) -> 7162.2876 | C11: =B11*12 -> 85947.452 | D11: =B11/$B$20 -> 0.0027456861 | E11: Hot+Cool+Archive WORM tiers, 7-year retention
A12: Confidential Ledger + Key Vault HSM | B12: =300000000*30*0.000005 + 2*3195 + 5000000/10000*0.15 -> 51465 | C12: =B12*12 -> 617580 | D12: =B12/$B$20 -> 0.019729274 | E12: Attestation ledger + HSM key ops for intent signing
A13: Service Bus Premium + Event Hubs + Event Grid | B13: =4*730*1.1 + 8*693 + 9000*0.6 + 25000*0.0004 -> 14166 | C13: =B13*12 -> 169992 | D13: =B13/$B$20 -> 0.0054305818 | E13: Async Intent/Exception/Evidence/Doctrine queues
A14: Sentinel + Monitor + App Insights (governance share) | B14: =(300000+120000+45000)*2.76*0.35 -> 449190 | C14: =B14*12 -> 5390280 | D14: =B14/$B$20 -> 0.17219844 | E14: 35% of observability allocated to ADAM (8-blueprint-layer telemetry)
A15: Azure AI Search + embeddings | B15: =3*3900 + 500*0.13 -> 11765 | C15: =B15*12 -> 141180 | D15: =B15/$B$20 -> 0.0045101507 | E15: Vector RAG for agent context retrieval
A16: Azure Policy + API Management (ADAM share) | B16: =260000*0.5*0.5 + 4*2795*0.4 -> 69472 | C16: =B16*12 -> 833664 | D16: =B16/$B$20 -> 0.026632315 | E16: OPA fallback + ADAM API gateway share
A17: Megaport cross-cloud fabric | B17: =6500 -> 6500 | C17: =B17*12 -> 78000 | D17: =B17/$B$20 -> 0.002491796 | E17: Azure ↔ AWS sync for CORE graph + Flight Recorder
A18: Entra ID P2 (workforce) | B18: =800*9 -> 7200 | C18: =B18*12 -> 86400 | D18: =B18/$B$20 -> 0.0027601432 | E18: Staff identity (agents authenticate via SPIFFE not Entra)
A19: SPIFFE/SPIRE operational overhead | B19: =4*583 -> 2332 | C19: =B19*12 -> 27984 | D19: =B19/$B$20 -> 0.00089397972 | E19: 4× D16s for SPIRE servers (workload identity)
A20: ADAM GOVERNANCE OVERLAY — MONTHLY TOTAL | B20: =SUM(B3:B19) -> 2608560.3 | C20: =B20*12 -> 31302723 | D20: =1 -> 1
A22: With EA + RI (25%) + 8% EA discount blended | B22: =B20*(1-Assumptions!$B$44)*(1-Assumptions!$B$43) -> 1799906.6 | C22: =B22*12 -> 21598879
A23: Per-subscriber ADAM overlay cost (monthly, committed) | B23: =(C22/Assumptions!$B$4)/12 -> 1.7999066

Sheet Consolidated OpEx
A1: Consolidated Cloud OpEx — 5-Year View
B2: Monthly (Y1) | C2: Year 1 | D2: Year 2 | E2: Year 3 | F2: Year 4 | G2: Year 5
A3: Azure Primary
A4: Azure Primary — committed OpEx | B4: ='Azure Primary'!F66 -> 2632285 | C4: =B4*12 -> 31587420 | D4: =C4*(1+Assumptions!$B$9)*(1-Assumptions!$B$45*0.7)*(1-Assumptions!$B$46*0.3*0.2) -> 32895796 | E4: =D4*(1+Assumptions!$B$9)*(1-Assumptions!$B$45*0.7)*(1-Assumptions!$B$46*0.3*0.2) -> 34258367 | F4: =E4*(1+Assumptions!$B$9)*(1-Assumptions!$B$45*0.7)*(1-Assumptions!$B$46*0.3*0.2) -> 35677376 | G4: =F4*(1+Assumptions!$B$9)*(1-Assumptions!$B$45*0.7)*(1-Assumptions!$B$46*0.3*0.2) -> 37155161
A5: AWS Standby — committed OpEx | B5: ='AWS Standby'!F55 -> 1324994.9 | C5: =B5*12 -> 15899938 | D5: =C5*(1+Assumptions!$B$9)*(1-Assumptions!$B$45*0.7) -> 16810687 | E5: =D5*(1+Assumptions!$B$9)*(1-Assumptions!$B$45*0.7) -> 17773603 | F5: =E5*(1+Assumptions!$B$9)*(1-Assumptions!$B$45*0.7) -> 18791675 | G5: =F5*(1+Assumptions!$B$9)*(1-Assumptions!$B$45*0.7) -> 19868062
A6: TOTAL CLOUD OpEx | B6: =SUM(B4:B5) -> 3957279.9 | C6: =SUM(C4:C5) -> 47487358 | D6: =SUM(D4:D5) -> 49706483 | E6: =SUM(E4:E5) -> 52031969 | F6: =SUM(F4:F5) -> 54469050 | G6: =SUM(G4:G5) -> 57023223
A7: Content amortization (ref only, not cloud) | B7: =Assumptions!$B$61*Assumptions!$B$4 -> 6500000 | C7: =B7*12 -> 78000000 | D7: =C7*(1+Assumptions!$B$9) -> 87360000 | E7: =D7*(1+Assumptions!$B$9) -> 97843200 | F7: =E7*(1+Assumptions!$B$9) -> 1.0958438e+08 | G7: =F7*(1+Assumptions!$B$9) -> 1.2273451e+08
A9: Unit Economics
A10: Subscribers (year-end) | B10: =Assumptions!$B$4 -> 1000000 | C10: =B10*(1+Assumptions!$B$9) -> 1120000 | D10: =C10*(1+Assumptions!$B$9) -> 1254400 | E10: =D10*(1+Assumptions!$B$9) -> 1404928 | F10: =E10*(1+Assumptions!$B$9) -> 1573519.4 | G10: =F10*(1+Assumptions!$B$9) -> 1762341.7
A11: Cloud OpEx per subscriber — annual | C11: =C6/C10 -> 42.399427 | D11: =D6/D10 -> 39.625704 | E11: =E6/E10 -> 37.035328 | F11: =F6/F10 -> 34.616066 | G11: =G6/G10 -> 32.356508
A12: Cloud OpEx per subscriber — monthly | C12: =C11/12 -> 3.5332856 | D12: =D11/12 -> 3.302142 | E12: =E11/12 -> 3.0862773 | F12: =F11/12 -> 2.8846722 | G12: =G11/12 -> 2.6963757

Sheet Revenue Model
A1: Revenue Model — Pricing Tiers × Subscriber Mix × 5-year growth
B2: Price ($/mo) | C2: Mix % | D2: Subs (Y1) | E2: Monthly $ (Y1) | F2: Annual $ (Y1) | G2: Notes
A3: Ad-supported | B3: =Assumptions!$B$52 -> 4.99 | C3: =Assumptions!$B$54 -> 0.2 | D3: =Assumptions!$B$4*C3 -> 200000 | E3: =B3*D3 -> 998000 | F3: =E3*12 -> 11976000
A4: Basic | B4: =Assumptions!$B$48 -> 7.99 | C4: =Assumptions!$B$55 -> 0.15 | D4: =Assumptions!$B$4*C4 -> 150000 | E4: =B4*D4 -> 1198500 | F4: =E4*12 -> 14382000
A5: Standard | B5: =Assumptions!$B$49 -> 13.99 | C5: =Assumptions!$B$56 -> 0.35 | D5: =Assumptions!$B$4*C5 -> 350000 | E5: =B5*D5 -> 4896500 | F5: =E5*12 -> 58758000
A6: Premium | B6: =Assumptions!$B$50 -> 19.99 | C6: =Assumptions!$B$57 -> 0.22 | D6: =Assumptions!$B$4*C6 -> 220000 | E6: =B6*D6 -> 4397800 | F6: =E6*12 -> 52773600
A7: Premium Plus | B7: =Assumptions!$B$51 -> 24.99 | C7: =Assumptions!$B$58 -> 0.08 | D7: =Assumptions!$B$4*C7 -> 80000 | E7: =B7*D7 -> 1999200 | F7: =E7*12 -> 23990400
A8: Ad revenue (on ad-supported tier) | B8: =Assumptions!$B$53 -> 6 | D8: =D3 -> 200000 | E8: =B8*D8 -> 1200000 | F8: =E8*12 -> 14400000
A9: TOTAL GROSS REVENUE — Y1 | C9: =SUM(C3:C7) -> 1 | D9: =SUM(D3:D7) -> 1000000 | E9: =SUM(E3:E8) -> 14690000 | F9: =E9*12 -> 176280000
A10: ARPU (avg revenue / paying sub / mo) | E10: =(E9-E8)/D9 -> 13.49
A11: Blended ARPU incl. ads | E11: =E9/D9 -> 14.69
A13: 5-Year Revenue Projection (flat pricing)
B14: Year 1 | C14: Year 2 | D14: Year 3 | E14: Year 4 | F14: Year 5
A15: Subscribers (year-avg) | B15: =Assumptions!$B$4 -> 1000000 | C15: =B15*(1+Assumptions!$B$9) -> 1120000 | D15: =C15*(1+Assumptions!$B$9) -> 1254400 | E15: =D15*(1+Assumptions!$B$9) -> 1404928 | F15: =E15*(1+Assumptions!$B$9) -> 1573519.4
A16: Gross revenue (flat pricing) | B16: =B15/Assumptions!$B$4*F9 -> 176280000 | C16: =C15/Assumptions!$B$4*F9 -> 1.974336e+08 | D16: =D15/Assumptions!$B$4*F9 -> 2.2112563e+08 | E16: =E15/Assumptions!$B$4*F9 -> 2.4766071e+08 | F16: =F15/Assumptions!$B$4*F9 -> 2.7737999e+08
A17: Gross revenue (+3% pricing / yr) | B17: =B16*(1.03)^0 -> 176280000 | C17: =C16*(1.03)^1 -> 2.0335661e+08 | D17: =D16*(1.03)^2 -> 2.3459218e+08 | E17: =E16*(1.03)^3 -> 2.7062554e+08 | F17: =F16*(1.03)^4 -> 3.1219363e+08
A18: Less: Payment processing (2.8%) | B18: =-B17*Assumptions!$B$59 -> -4935840 | C18: =-C17*Assumptions!$B$59 -> -5693985 | D18: =-D17*Assumptions!$B$59 -> -6568581.1 | E18: =-E17*Assumptions!$B$59 -> -7577515.2 | F18: =-F17*Assumptions!$B$59 -> -8741421.5
A19: NET REVENUE | B19: =B17+B18 -> 171344160 | C19: =C17+C18 -> 1.9766262e+08 | D19: =D17+D18 -> 2.280236e+08 | E19: =E17+E18 -> 2.6304803e+08 | F19: =F17+F18 -> 3.034522e+08

Sheet 5-Year P&L
A1: 5-Year P&L — ADAM + NetStreamX (in $000s)
A2: $000s | B2: Year 1 | C2: Year 2 | D2: Year 3 | E2: Year 4 | F2: Year 5
A3: Net Revenue (3% pricing growth) | B3: ='Revenue Model'!B19/1000 -> 171344.16 | C3: ='Revenue Model'!C19/1000 -> 197662.62 | D3: ='Revenue Model'!D19/1000 -> 228023.6 | E3: ='Revenue Model'!E19/1000 -> 263048.03 | F3: ='Revenue Model'!F19/1000 -> 303452.2
A4: COST OF REVENUE
A5: Cloud OpEx (Azure + AWS committed) | B5: ='Consolidated OpEx'!C6/1000 -> 47487.358 | C5: ='Consolidated OpEx'!D6/1000 -> 49706.483 | D5: ='Consolidated OpEx'!E6/1000 -> 52031.969 | E5: ='Consolidated OpEx'!F6/1000 -> 54469.05 | F5: ='Consolidated OpEx'!G6/1000 -> 57023.223
A6: Content amortization (excluded from cloud but shown) | B6: ='Consolidated OpEx'!C7/1000 -> 78000 | C6: ='Consolidated OpEx'!D7/1000 -> 87360 | D6: ='Consolidated OpEx'!E7/1000 -> 97843.2 | E6: ='Consolidated OpEx'!F7/1000 -> 109584.38 | F6: ='Consolidated OpEx'!G7/1000 -> 122734.51
A7: Gross Margin — Cloud only | B7: =B3-B5 -> 123856.8 | C7: =C3-C5 -> 147956.14 | D7: =D3-D5 -> 175991.63 | E7: =E3-E5 -> 208578.98 | F7: =F3-F5 -> 246428.98
A8: Gross Margin % — Cloud only | B8: =B7/B3 -> 0.72285394 | C8: =C7/C3 -> 0.74852867 | D8: =D7/D3 -> 0.77181323 | E8: =E7/E3 -> 0.79293116 | F8: =F7/F3 -> 0.81208499
A9: Gross Margin — after content | B9: =B3-B5-B6 -> 45856.802 | C9: =C3-C5-C6 -> 60596.14 | D9: =D3-D5-D6 -> 78148.432 | E9: =E3-E5-E6 -> 98994.593 | F9: =F3-F5-F6 -> 123694.47
A10: Gross Margin % | B10: =B9/B3 -> 0.26762979 | C10: =C9/C3 -> 0.30656347 | D10: =D9/D3 -> 0.34272081 | E10: =E9/E3 -> 0.37633657 | F10: =F9/F3 -> 0.40762423
A12: Cumulative Totals (1 / 3 / 5-year)
A13: Cumulative Revenue | B13: =B3 -> 171344.16 | D13: =SUM(B3:D3) -> 597030.38 | F13: =SUM(B3:F3) -> 1163530.6
A14: Cumulative Cloud OpEx | B14: =B5 -> 47487.358 | D14: =SUM(B5:D5) -> 149225.81 | F14: =SUM(B5:F5) -> 260718.08
A15: Cumulative Content | B15: =B6 -> 78000 | D15: =SUM(B6:D6) -> 263203.2 | F15: =SUM(B6:F6) -> 495522.09

Sheet Pricing Scenarios
A1: Pricing Scenarios — List vs Committed vs Future (annual)
A2: Scenario | B2: Azure Primary | C2: AWS Standby | D2: Total Cloud OpEx | E2: OpEx per sub ($/yr)
A3: Current LIST pricing — Year 1 (no commitments) | B3: ='Azure Primary'!F63*12 -> 45778870 | C3: ='AWS Standby'!F52*12 -> 23555464 | D3: =B3+C3 -> 69334334 | E3: =D3/Assumptions!$B$4 -> 69.334334
A4: Current COMMITTED — Year 1 (EA + 3yr RI/SP) | B4: ='Azure Primary'!F66*12 -> 31587420 | C4: ='AWS Standby'!F55*12 -> 15899938 | D4: =B4+C4 -> 47487358 | E4: =D4/Assumptions!$B$4 -> 47.487358
A5: Future — Year 3 (committed + price deflation + 12%/yr sub growth) | B5: ='Consolidated OpEx'!E4 -> 34258367 | C5: ='Consolidated OpEx'!E5 -> 17773603 | D5: =B5+C5 -> 52031969 | E5: =D5/( 'Consolidated OpEx'!E10 ) -> 37.035328
A6: Future — Year 5 (committed + deflation + 12%/yr sub growth) | B6: ='Consolidated OpEx'!G4 -> 37155161 | C6: ='Consolidated OpEx'!G5 -> 19868062 | D6: =B6+C6 -> 57023223 | E6: =D6/( 'Consolidated OpEx'!G10 ) -> 32.356508
A8: Impact of Commitments + Deflation (savings vs LIST Year 1)
A9: List-to-Committed savings (Y1) | D9: =D3-D4 -> 21846975 | E9: =D9/D3 -> 0.31509606

Sheet Competitive Bench
A1: Competitive Benchmark — ARPU, Margin, Tier Pricing (2026)
A2: Platform | B2: Subs (M) | C2: ARPU ($/mo) | D2: Entry tier $ | E2: Mid tier $ | F2: Top tier $ | G2: GM % | H2: Positioning / notes
A3: Netflix | B3: 294 | C3: 17.3 | D3: 7.99 | E3: 17.99 | F3: 24.99 | G3: 0.45 | H3: Largest; price-lead; ad-tier $7.99. Premium w/ 4K at $24.99 US.
A4: Disney+ / Bundle | B4: 155 | C4: 8.2 | D4: 9.99 | E4: 13.99 | F4: 19.99 | G4: 0.22 | H4: Lower ARPU; bundles Hulu+ESPN lift US ARPU. Aggressive family price.
A5: Max (Warner Bros) | B5: 95 | C5: 11.9 | D5: 9.99 | E5: 16.99 | F5: 20.99 | G5: 0.28 | H5: Premium sports/HBO content. Ultimate UHD tier at $20.99.
A6: Paramount+ | B6: 77 | C6: 7.5 | D6: 7.99 | E6: 12.99 | F6: 14.99 | G6: 0.12 | H6: Live TV + CBS news; lower ARPU; challenged margins.
A7: Apple TV+ | B7: 50 | C7: 9.99 | D7: 9.99 | E7: 9.99 | F7: 9.99 | G7: n/d | H7: Single tier; subsidizes via hardware halo.
A8: Prime Video | B8: 200 | C8: 10 | D8: 8.99 | E8: 8.99 | F8: 14.99 | G8: n/d | H8: Bundled inside Prime; 'true' streaming ARPU hard to isolate.
A9: Hulu (ex Disney bundle) | B9: 50 | C9: 9.8 | D9: 9.99 | E9: 18.99 | F9: 82.99 | G9: 0.15 | H9: No-ads + live TV skew ARPU up; aggressive on ads.
A10: Mubi | B10: 1 | C10: 14.5 | D10: 12.99 | E10: 12.99 | F10: 19.99 | G10: 0.3 | H10: Curated art house; niche but premium margins.
A11: NETSTREAMX (this model) | B11: 1 | C11: =('Revenue Model'!E9-'Revenue Model'!E8)/'Revenue Model'!D9 -> 13.49 | D11: 4.99 | E11: 13.99 | F11: 24.99 | G11: =('5-Year P&L'!B7)/('5-Year P&L'!B3) -> 0.72285394 | H11: This model — matches mid-market streamer positioning with ADAM governance built in.
A13: Key observations
A14: Mid-market SVODs (100 K–1 M subs) cluster at $11–14 ARPU. Below $10 ARPU, only bundle plays (Disney, Prime) survive.
A15: Premium UHD tier top end is $20–25. Anything above $25 requires either live sports (Hulu+LiveTV) or multi-brand bundles.
A16: Mature streamers are targeting 30–35 % cloud-excl gross margin; Netflix leads at 45 % via OpenConnect (private CDN).
A17: Ad-supported tier is now table stakes — contributes 15–25 % of revenue at $4–8 price and ~$6 ARPU in ads.
A18: Content amortization, NOT cloud, drives P&L. A 100K-title library is 'mid-tier' — $0.5–1B/yr amortized; big 5 run 2–20×.
A19: ADAM governance overlay adds ~$1–3 / sub / year — material vs raw cost but ~0.5–1% of ARPU; more than paid back in exception savings + regulatory fine avoidance.

Sheet Recommendations
A1: Pricing Recommendations — Sustain & Grow
A2: Recommended Tier | B2: Price / mo | C2: Mix target | D2: ARPU contribution | E2: Rationale
A3: Ad-supported (HD) | B3: =4.99 -> 4.99 | C3: =20% -> 0.2 | D3: =B3*C3 -> 0.998 | E3: Funnel tier; ad revenue pushes effective ARPU to ~$11/mo. Keep free-trial conversion tied to this.
A4: Basic (HD, 1 stream) | B4: =8.99 -> 8.99 | C4: =15% -> 0.15 | D4: =B4*C4 -> 1.3485 | E4: Raise $1 vs current $7.99 to match Netflix Basic. Minimal churn risk at this tier.
A5: Standard (HD, 2 streams) | B5: =14.99 -> 14.99 | C5: =35% -> 0.35 | D5: =B5*C5 -> 5.2465 | E5: Core profit tier. $1 raise to $14.99 closes the gap to Netflix Standard and adds ~$4M/yr net.
A6: Premium (UHD, 4 streams) | B6: =21.99 -> 21.99 | C6: =22% -> 0.22 | D6: =B6*C6 -> 4.8378 | E6: Raise $2 to $21.99. Pricing aligns with Max Ultimate and signals premium content commitment.
A7: Premium Plus (UHD + bundled) | B7: =27.99 -> 27.99 | C7: =8% -> 0.08 | D7: =B7*C7 -> 2.2392 | E7: New anchor tier — UHD + Dolby Atmos + downloads + 2 guest passes + early access. Justifies UHD CDN costs.
A8: Recommended blended ARPU (paying subs only) | D8: =SUMPRODUCT(B3:B7,C3:C7)/SUM(C4:C7) -> 18.3375
A10: Break-even Pricing Calculator
A11: Cloud OpEx per sub per month (Y1, committed) | B11: ='Consolidated OpEx'!C11/12 -> 3.5332856
A12: Content amort. per sub per month | B12: =Assumptions!$B$61 -> 6.5
A13: Target gross margin % | B13: 0.35
A14: Minimum ARPU to achieve target GM | B14: =(B11+B12)/(1-B13) -> 15.435824
A15: Gap vs recommended blended ARPU | B15: =D8-B14 -> 2.901676
A17: Business Recommendations (summary)
A18: PRICE | B18: Raise blended ARPU to ~$14.50 (from ~$12.10). Standard + Premium tiers absorb $1–2 increases with <1 % churn impact at this scale.
A19: TIERING | B19: Introduce Premium Plus at $27.99 to capture top 5–8 % of heavy UHD watchers; provides an anchor that lifts perceived value of Premium.
A20: COMMIT | B20: Move to 3-year Microsoft EA + 3-yr Azure Savings Plans immediately; lock 25–30 % discount vs list and stabilize cost curve.
A21: DR ECONOMICS | B21: Keep AWS at 30 % warm; validate a 'pilot-light' (10 %) scenario for years 2-3 once Azure MTBF justifies — saves ~$4–6 M/yr.
A22: CDN | B22: Dual-source CDN (CloudFront + a specialist — Akamai or Fastly) with contracted ~$0.012/GB at PB scale; build peering to top 15 ISPs in EU/NA.
A23: AI COST | B23: Route 85 % of agent decisions to GPT-4o-mini; reserve GPT-4o for Governor layer only. Implement a semantic cache (30 % hit rate on recurring intents) for ~$2 M/yr saving.
A24: ADAM VALUE | B24: The ADAM overlay adds $1–3/sub/yr — fund it from reducing exception SLA breaches (estimated $0.20–0.60/sub/mo from rights & fraud incidents).
A25: CONTENT | B25: Cloud OpEx is NOT the binding constraint — content spend is. Every $1 cut in content ROI is worth 10× a $1 cut in cloud.
